Workbook

Sheet NOTAS
A1: TRAYECTO:
A2: INSTRUCTOR:
A3: SEDE:
A4: ALUMNO (PEGAR APELLIDOS EN COLUMNA IZQUIERDA Y NOMBRE EN LA DERECHA) | C4: NOTAS - DE NECESITAR, INSERTAS MAS COLUMAS EN EL LUGAR QUE CORRESPONDE | DG4: ASISTENCIA | DZ4: ACTA 1 | EA4: ACTA 2 | EB4: ACTA 3 | EC4: ACTA 4 | ED4: ACTA 5 | EE4: ACTA 6 | EF4: ACTA 7 | EG4: ACTA 8 | EH4: ACTA 9 | EI4: PROMEDIO | EJ4: FUNDAMENTACIÓN DESEMPEÑO INDIVIDUAL | EK4: FUNDAMENTACIÓN DESEMPEÑO EN EQUIPO | EL4: OBSERVACIONES / REFERENCIAL DE INGRESO | EN4: MARZO | EO4: ABRIL | EP4: ABRIL 2 | EQ4: MAYO | ER4: MAYO 2 | ES4: JUNIO | ET4: JUNIO 2 | EU4: JULIO | EV4: JULIO 2 | EW4: AGOSTO | EX4: AGOSTO 2 | EY4: SEPTIEMBRE | EZ4: SEPTIEMBRE-2 | FA4: SEPTIEMBRE-3 | FB4: OCTUBRE | FC4: OCTUBRE-2 | FD4: NOVIEMBRE | FE4: NOVIEMBRE-2 | FF4: DICIEMBRE | FG4: OBSERVACION CALIFICACIONES NO TOCAR | FH4: BARRA DE PROGRESO
DG5: MARZO | DH5: ABRIL | DI5: ABRIL 2 | DJ5: MAYO | DK5: MAYO 2 | DL5: JUNIO | DM5: JUNIO 2 | DN5: JULIO | DO5: JULIO 2 | DP5: AGOSTO | DQ5: AGOSTO 2 | DR5: SEPTIEMBRE | DS5: SEPTIEMBRE 2 | DT5: SEPTIEMBRE 3 | DU5: OCTUBRE | DV5: OCTUBRE 2 | DW5: NOVIEMBRE | DX5: NOVIEMBRE 2 | DY5: DICIEMBRE
C6: MOD 1 | D6: MOD 1 | E6: MOD 1 | F6: MOD 1 | G6: MOD 1 | H6: MOD 1 | I6: MOD 1 | J6: MOD 1 | K6: MOD 1 | L6: MOD 1 | M6: MOD 1 | N6: NOTA ASISTENCIA | O6: MOD 2 | P6: MOD 2 | Q6: MOD 2 | R6: MOD 2 | S6: MOD 2 | T6: MOD 2 | U6: MOD 2 | V6: MOD 2 | W6: MOD 2 | X6: MOD 2 | Y6: MOD 2 | Z6: NOTA ASISTENCIA | AA6: MOD 3 | AB6: MOD 3 | AC6: MOD 3 | AD6: MOD 3 | AE6: MOD 3 | AF6: MOD 3 | AG6: MOD 3 | AH6: MOD 3 | AI6: MOD 3 | AJ6: MOD 3 | AK6: MOD 3 | AL6: NOTA ASISTENCIA | AM6: MOD 4 | AN6: MOD 4 | AO6: MOD 4 | AP6: MOD 4 | AQ6: MOD 4 | AR6: MOD 4 | AS6: MOD 4 | AT6: MOD 4 | AU6: MOD 4 | AV6: MOD 4 | AW6: MOD 4 | AX6: NOTA ASISTENCIA | AY6: MOD 5 | AZ6: MOD 5 | BA6: MOD 5 | BB6: MOD 5 | BC6: MOD 5 | BD6: MOD 5 | BE6: MOD 5 | BF6: MOD 5 | BG6: MOD 5 | BH6: MOD 5 | BI6: MOD 5 | BJ6: NOTA ASISTENCIA | BK6: MOD 6 | BL6: MOD 6 | BM6: MOD 6 | BN6: MOD 6 | BO6: MOD 6 | BP6: MOD 6 | BQ6: MOD 6 | BR6: MOD 6 | BS6: MOD 6 | BT6: MOD 6 | BU6: MOD 6 | BV6: NOTA ASISTENCIA | BW6: MOD 7 | BX6: MOD 7 | BY6: MOD 7 | BZ6: MOD 7 | CA6: MOD 7 | CB6: MOD 7 | CC6: MOD 7 | CD6: MOD 7 | CE6: MOD 7 | CF6: MOD 7 | CG6: MOD 7 | CH6: NOTA ASISTENCIA | CI6: MOD 8 | CJ6: MOD 8 | CK6: MOD 8 | CL6: MOD 8 | CM6: MOD 8 | CN6: MOD 8 | CO6: MOD 8 | CP6: MOD 8 | CQ6: MOD 8 | CR6: MOD 8 | CS6: MOD 8 | CT6: NOTA ASISTENCIA | CU6: MOD 9 | CV6: MOD 9 | CW6: MOD 9 | CX6: MOD 9 | CY6: MOD 9 | CZ6: MOD 9 | DA6: MOD 9 | DB6: MOD 9 | DC6: MOD 9 | DD6: MOD 9 | DE6: MOD 9 | DF6: NOTA ASISTENCIA
EN7: =MARZO!$T$7 | EO7: =ABRIL!$T$7 | EP7: ='ABRIL 2'!$T$7 | EQ7: =MAYO!$T$7 | ER7: ='MAYO 2'!$T$7 | ES7: =JUNIO!$T$7 | ET7: ='JUNIO 2'!$T$7 | EU7: =JULIO!$T$7 | EV7: ='JULIO 2'!$T$7 | EW7: =AGOSTO!$T$7 | EX7: ='AGOSTO 2'!$T$7 | EY7: =SEPTIEMBRE!$T$7 | EZ7: ='SEPTIEMBRE 2'!$T$7 | FA7: ='SEPTIEMBRE 3'!$T$7 | FB7: =OCTUBRE!$T$7 | FC7: ='OCTUBRE 2'!$T$7 | FD7: =NOVIEMBRE!$T$7 | FE7: ='NOVIEMBRE 2'!$T$7 | FF7: =DICIEMBRE!T7
N8: =IFERROR(SUM(DT8:DU8)/SUM($DT$7:$DU$7)*100,"") | Z8: =IFERROR(SUM(EB8:EC8)/SUM($EB$7:$EC$7)*100,"") | AL8: =IFERROR(SUM(EK8:EL8)/SUM($EK$7:$EL$7)*100,"") | AX8: =IFERROR(SUM(EW8:EY8)/SUM($EW$7:$EY$7)*100,"") | BJ8: =IFERROR(SUM(EZ8)/SUM($EZ$7)*100,"") | BV8: =IFERROR(SUM(FA8:FB8)/SUM($FA$7:$FB$7)*100,"") | CH8: =IFERROR(SUM(FC8:FD8)/SUM($FC$7:$FD$7)*100,"") | CT8: =IFERROR(SUM(FE8:FF8)/SUM($FE$7:$FF$7)*100,"") | DG8: {=IFERROR(_xlfn.XLOOKUP($A8&B8,MARZO!$D$11:$D$40&MARZO!$E$11:$E$40,MARZO!$AM$11:$AM$40,_xlfn.XLOOKUP($A8&$B8,MARZO!$BC$11:$BC$40&MARZO!$BD$11:$BD$40,MARZO!$CL$11:$CL$40,"A"))/1%,"")} | DH8: {=IFERROR(_xlfn.XLOOKUP($A8&$B8,ABRIL!$D$11:$D$40&ABRIL!$E$11:$E$40,ABRIL!$AM$11:$AM$40,_xlfn.XLOOKUP($A8&$B8,ABRIL!$BC$11:$BC$40&ABRIL!$BD$11:$BD$40,ABRIL!$CL$11:$CL$40,"A"))/1%,"")} | DI8: {=IFERROR(_xlfn.XLOOKUP($A8&$B8,'ABRIL 2'!$D$11:$D$40&'ABRIL 2'!$E$11:$E$40,'ABRIL 2'!$AM$11:$AM$40,_xlfn.XLOOKUP($A8&$B8,'ABRIL 2'!$BC$11:$BC$40&'ABRIL 2'!$BD$11:$BD$40,'ABRIL 2'!$CL$11:$CL$40,"A"))/1%,"")} | DJ8: {=IFERROR(_xlfn.XLOOKUP($A8&$B8,MAYO!$D$11:$D$40&MAYO!$E$11:$E$40,MAYO!$AM$11:$AM$40,_xlfn.XLOOKUP($A8&$B8,MAYO!$BC$11:$BC$40&MAYO!$BD$11:$BD$40,MAYO!$CL$11:$CL$40,"A"))/1%,"")} | DK8: {=IFERROR(_xlfn.XLOOKUP($A8&$B8,'MAYO 2'!$D$11:$D$40&'MAYO 2'!$E$11:$E$40,'MAYO 2'!$AM$11:$AM$40,_xlfn.XLOOKUP($A8&$B8,'MAYO 2'!$BC$11:$BC$40&'MAYO 2'!$BD$11:$BD$40,'MAYO 2'!$CL$11:$CL$40,"A"))/1%,"")} | DL8: {=IFERROR(_xlfn.XLOOKUP($A8&$B8,JUNIO!$D$11:$D$40&JUNIO!$E$11:$E$40,JUNIO!$AM$11:$AM$40,_xlfn.XLOOKUP($A8&$B8,JUNIO!$BC$11:$BC$40&JUNIO!$BD$11:$BD$40,JUNIO!$CL$11:$CL$40,"A"))/1%,"")} | DM8: {=IFERROR(_xlfn.XLOOKUP($A8&$B8,'JUNIO 2'!$D$11:$D$40&'JUNIO 2'!$E$11:$E$40,'JUNIO 2'!$AM$11:$AM$40,_xlfn.XLOOKUP($A8&$B8,'JUNIO 2'!$BC$11:$BC$40&'JUNIO 2'!$BD$11:$BD$40,'JUNIO 2'!$CL$11:$CL$40,"A"))/1%,"")} | DN8: {=IFERROR(_xlfn.XLOOKUP($A8&$B8,JULIO!$D$11:$D$40&JULIO!$E$11:$E$40,JULIO!$AM$11:$AM$40,_xlfn.XLOOKUP($A8&$B8,JULIO!$BC$11:$BC$40&JULIO!$BD$11:$BD$40,JULIO!$CL$11:$CL$40,"A"))/1%,"")} | DO8: {=IFERROR(_xlfn.XLOOKUP($A8&$B8,'JULIO 2'!$D$11:$D$40&'JULIO 2'!$E$11:$E$40,'JULIO 2'!$AM$11:$AM$40,_xlfn.XLOOKUP($A8&$B8,'JULIO 2'!$BC$11:$BC$40&'JULIO 2'!$BD$11:$BD$40,'JULIO 2'!$CL$11:$CL$40,"A"))/1%,"")} | DP8: {=IFERROR(_xlfn.XLOOKUP($A8&$B8,AGOSTO!$D$11:$D$40&AGOSTO!$E$11:$E$40,AGOSTO!$AM$11:$AM$40,_xlfn.XLOOKUP($A8&$B8,AGOSTO!$BC$11:$BC$40&AGOSTO!$BD$11:$BD$40,AGOSTO!$CL$11:$CL$40,"A"))/1%,"")} | DQ8: {=IFERROR(_xlfn.XLOOKUP($A8&$B8,'AGOSTO 2'!$D$11:$D$40&'AGOSTO 2'!$E$11:$E$40,'AGOSTO 2'!$AM$11:$AM$40,_xlfn.XLOOKUP($A8&$B8,'AGOSTO 2'!$BC$11:$BC$40&'AGOSTO 2'!$BD$11:$BD$40,'AGOSTO 2'!$CL$11:$CL$40,"A"))/1%,"")} | DR8: {=IFERROR(_xlfn.XLOOKUP($A8&$B8,SEPTIEMBRE!$D$11:$D$40&SEPTIEMBRE!$E$11:$E$40,SEPTIEMBRE!$AM$11:$AM$40,_xlfn.XLOOKUP($A8&$B8,SEPTIEMBRE!$BC$11:$BC$40&SEPTIEMBRE!$BD$11:$BD$40,SEPTIEMBRE!$CL$11:$CL$40,"A"))/1%,"")} | DS8: {=IFERROR(_xlfn.XLOOKUP($A8&$B8,'SEPTIEMBRE 2'!$D$11:$D$40&'SEPTIEMBRE 2'!$E$11:$E$40,'SEPTIEMBRE 2'!$AM$11:$AM$40,_xlfn.XLOOKUP($A8&$B8,'SEPTIEMBRE 2'!$BC$11:$BC$40&'SEPTIEMBRE 2'!$BD$11:$BD$40,'SEPTIEMBRE 2'!$CL$11:$CL$40,"A"))/1%,"")} | DT8: {=IFERROR(_xlfn.XLOOKUP($A8&$B8,'SEPTIEMBRE 3'!$D$11:$D$40&'SEPTIEMBRE 3'!$E$11:$E$40,'SEPTIEMBRE 3'!$AM$11:$AM$40,_xlfn.XLOOKUP($A8&$B8,'SEPTIEMBRE 3'!$BC$11:$BC$40&'SEPTIEMBRE 3'!$BD$11:$BD$40,'SEPTIEMBRE 3'!$CL$11:$CL$40,"A"))/1%,"")} | DU8: {=IFERROR(_xlfn.XLOOKUP($A8&$B8,OCTUBRE!$D$11:$D$40&OCTUBRE!$E$11:$E$40,OCTUBRE!$AM$11:$AM$40,_xlfn.XLOOKUP($A8&$B8,OCTUBRE!$BC$11:$BC$40&OCTUBRE!$BD$11:$BD$40,OCTUBRE!$CL$11:$CL$40,"A"))/1%,"")} | DV8: {=IFERROR(_xlfn.XLOOKUP($A8&$B8,'OCTUBRE 2'!$D$11:$D$40&'OCTUBRE 2'!$E$11:$E$40,'OCTUBRE 2'!$AM$11:$AM$40,_xlfn.XLOOKUP($A8&$B8,'OCTUBRE 2'!$BC$11:$BC$40&'OCTUBRE 2'!$BD$11:$BD$40,'OCTUBRE 2'!$CL$11:$CL$40,"A"))/1%,"")} | DW8: {=IFERROR(_xlfn.XLOOKUP($A8&$B8,NOVIEMBRE!$D$11:$D$40&NOVIEMBRE!$E$11:$E$40,NOVIEMBRE!$AM$11:$AM$40,_xlfn.XLOOKUP($A8&$B8,NOVIEMBRE!$BC$11:$BC$40&NOVIEMBRE!$BD$11:$BD$40,NOVIEMBRE!$CL$11:$CL$40,"A"))/1%,"")} | DX8: {=IFERROR(_xlfn.XLOOKUP($A8&$B8,'NOVIEMBRE 2'!$D$11:$D$40&'NOVIEMBRE 2'!$E$11:$E$40,'NOVIEMBRE 2'!$AM$11:$AM$40,_xlfn.XLOOKUP($A8&$B8,'NOVIEMBRE 2'!$BC$11:$BC$40&'NOVIEMBRE 2'!$BD$11:$BD$40,'NOVIEMBRE 2'!$CL$11:$CL$40,"A"))/1%,"")} | DY8: {=IFERROR(_xlfn.XLOOKUP($A8&$B8,DICIEMBRE!$D$11:$D$40&DICIEMBRE!$E$11:$E$40,DICIEMBRE!$AM$11:$AM$40,_xlfn.XLOOKUP($A8&$B8,DICIEMBRE!$BC$11:$BC$40&DICIEMBRE!$BD$11:$BD$40,DICIEMBRE!$CL$11:$CL$40,"A"))/1%,"")} | DZ8: =IFERROR(IF(COUNTIF(C8:N8,"-"),"A",ROUND(AVERAGE(C8:N8),0)),"-") -> - | EA8: =IFERROR(IF(COUNTIF(O8:Z8,"-"),"A",ROUND(AVERAGE(O8:Z8),0)),"-") -> - | EB8: =IFERROR(IF(COUNTIF(AA8:AL8,"-"),"A",ROUND(AVERAGE(AA8:AL8),0)),"-") -> - | EC8: =IFERROR(IF(COUNTIF(AM8:AX8,"-"),"A",ROUND(AVERAGE(AM8:AX8),0)),"-") -> - | ED8: =IFERROR(IF(COUNTIF(AY8:BJ8,"-"),"A",ROUND(AVERAGE(AY8:BJ8),0)),"-") -> - | EE8: =IFERROR(IF(COUNTIF(BK8:BV8,"-"),"A",ROUND(AVERAGE(BK8:BV8),0)),"-") -> - | EF8: =IFERROR(IF(COUNTIF(BW8:CH8,"-"),"A",ROUND(AVERAGE(BW8:CH8),0)),"-") -> - | EG8: =IFERROR(IF(COUNTIF(CI8:CT8,"-"),"A",ROUND(AVERAGE(CI8:CT8),0)),"-") -> - | EH8: =IFERROR(IF(COUNTIF(CU8:DF8,"-"),"A",ROUND(AVERAGE(CU8:DF8),0)),"-") -> - | EI8: =IFERROR(ROUND(AVERAGE(DZ8:EH8),0),"") | EN8: {=IFERROR(_xlfn.XLOOKUP($A8&$B8,MARZO!$D$11:$D$40&MARZO!$E$11:$E$40,MARZO!$AK$11:$AK$40,_xlfn.XLOOKUP($A8&$B8,MARZO!$BC$11:$BC$40&MARZO!$BD$11:$BD$40,MARZO!$CJ$11:$CJ$40,"A")),"")} -> 0 | EO8: {=IFERROR(_xlfn.XLOOKUP($A8&$B8,ABRIL!$D$11:$D$40&ABRIL!$E$11:$E$40,ABRIL!$AK$11:$AK$40,_xlfn.XLOOKUP($A8&$B8,ABRIL!$BC$11:$BC$40&ABRIL!$BD$11:$BD$40,ABRIL!$CJ$11:$CJ$40,"A")),"")} -> 0 | EP8: {=IFERROR(_xlfn.XLOOKUP($A8&$B8,'ABRIL 2'!$D$11:$D$40&'ABRIL 2'!$E$11:$E$40,'ABRIL 2'!$AK$11:$AK$40,_xlfn.XLOOKUP($A8&$B8,'ABRIL 2'!$BC$11:$BC$40&'ABRIL 2'!$BD$11:$BD$40,'ABRIL 2'!$CJ$11:$CJ$40,"A")),"")} -> 0 | EQ8: {=IFERROR(_xlfn.XLOOKUP($A8&$B8,MAYO!$D$11:$D$40&MAYO!$E$11:$E$40,MAYO!$AK$11:$AK$40,_xlfn.XLOOKUP($A8&$B8,MAYO!$BC$11:$BC$40&MAYO!$BD$11:$BD$40,MAYO!$CJ$11:$CJ$40,"A")),"")} -> 0 | ER8: {=IFERROR(_xlfn.XLOOKUP($A8&$B8,'MAYO 2'!$D$11:$D$40&'MAYO 2'!$E$11:$E$40,'MAYO 2'!$AK$11:$AK$40,_xlfn.XLOOKUP($A8&$B8,'MAYO 2'!$BC$11:$BC$40&'MAYO 2'!$BD$11:$BD$40,'MAYO 2'!$CJ$11:$CJ$40,"A")),"")} -> 0 | ES8: {=IFERROR(_xlfn.XLOOKUP($A8&$B8,JUNIO!$D$11:$D$40&JUNIO!$E$11:$E$40,JUNIO!$AK$11:$AK$40,_xlfn.XLOOKUP($A8&$B8,JUNIO!$BC$11:$BC$40&JUNIO!$BD$11:$BD$40,JUNIO!$CJ$11:$CJ$40,"A")),"")} -> 0 | ET8: {=IFERROR(_xlfn.XLOOKUP($A8&$B8,'JUNIO 2'!$D$11:$D$40&'JUNIO 2'!$E$11:$E$40,'JUNIO 2'!$AK$11:$AK$40,_xlfn.XLOOKUP($A8&$B8,'JUNIO 2'!$BC$11:$BC$40&'JUNIO 2'!$BD$11:$BD$40,'JUNIO 2'!$CJ$11:$CJ$40,"A")),"")} -> 0 | EU8: {=IFERROR(_xlfn.XLOOKUP($A8&$B8,JULIO!$D$11:$D$40&JULIO!$E$11:$E$40,JULIO!$AK$11:$AK$40,_xlfn.XLOOKUP($A8&$B8,JULIO!$BC$11:$BC$40&JULIO!$BD$11:$BD$40,JULIO!$CJ$11:$CJ$40,"A")),"")} -> 0 | EV8: {=IFERROR(_xlfn.XLOOKUP($A8&$B8,'JULIO 2'!$D$11:$D$40&'JULIO 2'!$E$11:$E$40,'JULIO 2'!$AK$11:$AK$40,_xlfn.XLOOKUP($A8&$B8,'JULIO 2'!$BC$11:$BC$40&'JULIO 2'!$BD$11:$BD$40,'JULIO 2'!$CJ$11:$CJ$40,"A")),"")} -> 0 | EW8: {=IFERROR(_xlfn.XLOOKUP($A8&$B8,AGOSTO!$D$11:$D$40&AGOSTO!$E$11:$E$40,AGOSTO!$AK$11:$AK$40,_xlfn.XLOOKUP($A8&$B8,AGOSTO!$BC$11:$BC$40&AGOSTO!$BD$11:$BD$40,AGOSTO!$CJ$11:$CJ$40,"A")),"")} -> 0 | EX8: {=IFERROR(_xlfn.XLOOKUP($A8&$B8,'AGOSTO 2'!$D$11:$D$40&'AGOSTO 2'!$E$11:$E$40,'AGOSTO 2'!$AK$11:$AK$40,_xlfn.XLOOKUP($A8&$B8,'AGOSTO 2'!$BC$11:$BC$40&'AGOSTO 2'!$BD$11:$BD$40,'AGOSTO 2'!$CJ$11:$CJ$40,"A")),"")} -> 0 | EY8: {=IFERROR(_xlfn.XLOOKUP($A8&$B8,SEPTIEMBRE!$D$11:$D$40&SEPTIEMBRE!$E$11:$E$40,SEPTIEMBRE!$AK$11:$AK$40,_xlfn.XLOOKUP($A8&$B8,SEPTIEMBRE!$BC$11:$BC$40&SEPTIEMBRE!$BD$11:$BD$40,SEPTIEMBRE!$CJ$11:$CJ$40,"A")),"")} -> 0 | EZ8: {=IFERROR(_xlfn.XLOOKUP($A8&$B8,'SEPTIEMBRE 2'!$D$11:$D$40&'SEPTIEMBRE 2'!$E$11:$E$40,'SEPTIEMBRE 2'!$AK$11:$AK$40,_xlfn.XLOOKUP($A8&$B8,'SEPTIEMBRE 2'!$BC$11:$BC$40&'SEPTIEMBRE 2'!$BD$11:$BD$40,'SEPTIEMBRE 2'!$CJ$11:$CJ$40,"A")),"")} -> 0 | FA8: {=IFERROR(_xlfn.XLOOKUP($A8&$B8,'SEPTIEMBRE 3'!$D$11:$D$40&'SEPTIEMBRE 3'!$E$11:$E$40,'SEPTIEMBRE 3'!$AK$11:$AK$40,_xlfn.XLOOKUP($A8&$B8,'SEPTIEMBRE 3'!$BC$11:$BC$40&'SEPTIEMBRE 3'!$BD$11:$BD$40,'SEPTIEMBRE 3'!$CJ$11:$CJ$40,"A")),"")} -> 0 | FB8: {=IFERROR(_xlfn.XLOOKUP($A8&$B8,OCTUBRE!$D$11:$D$40&OCTUBRE!$E$11:$E$40,OCTUBRE!$AK$11:$AK$40,_xlfn.XLOOKUP($A8&$B8,OCTUBRE!$BC$11:$BC$40&OCTUBRE!$BD$11:$BD$40,OCTUBRE!$CJ$11:$CJ$40,"A")),"")} -> 0 | FC8: {=IFERROR(_xlfn.XLOOKUP($A8&$B8,'OCTUBRE 2'!$D$11:$D$40&'OCTUBRE 2'!$E$11:$E$40,'OCTUBRE 2'!$AK$11:$AK$40,_xlfn.XLOOKUP($A8&$B8,'OCTUBRE 2'!$BC$11:$BC$40&'OCTUBRE 2'!$BD$11:$BD$40,'OCTUBRE 2'!$CJ$11:$CJ$40,"A")),"")} -> 0 | FD8: {=IFERROR(_xlfn.XLOOKUP($A8&$B8,NOVIEMBRE!$D$11:$D$40&NOVIEMBRE!$E$11:$E$40,NOVIEMBRE!$AK$11:$AK$40,_xlfn.XLOOKUP($A8&$B8,NOVIEMBRE!$BC$11:$BC$40&NOVIEMBRE!$BD$11:$BD$40,NOVIEMBRE!$CJ$11:$CJ$40,"A")),"")} -> 0 | FE8: {=IFERROR(_xlfn.XLOOKUP($A8&$B8,'NOVIEMBRE 2'!$D$11:$D$40&'NOVIEMBRE 2'!$E$11:$E$40,'NOVIEMBRE 2'!$AK$11:$AK$40,_xlfn.XLOOKUP($A8&$B8,'NOVIEMBRE 2'!$BC$11:$BC$40&'NOVIEMBRE 2'!$BD$11:$BD$40,'NOVIEMBRE 2'!$CJ$11:$CJ$40,"A")),"")} -> 0 | FF8: {=IFERROR(_xlfn.XLOOKUP($A8&$B8,DICIEMBRE!$D$11:$D$40&DICIEMBRE!$E$11:$E$40,DICIEMBRE!$AK$11:$AK$40,_xlfn.XLOOKUP($A8&$B8,DICIEMBRE!$BC$11:$BC$40&DICIEMBRE!$BD$11:$BD$40,DICIEMBRE!$CJ$11:$CJ$40,"A")),"")} -> 0 | FG8: =IF( AND(N8="", Z8="", AL8="", AX8="", BJ8="", BV8="", CH8="", CT8="",DF8=""), "", TEXTJOIN( " ", TRUE, IF(AND(N8<>"", N8>=40, COUNTA(C8:M8)=0), "⚠️Faltan notas del Módulo I", ""), IF(AND(Z8<>"", Z8>=40, COUNTA(O8:Y8)=0), "⚠️Faltan notas del Módulo II", ""), IF(AND(AL8<>"", AL8>=40, COUNTA(AA8:AK8)=0), "⚠️Faltan notas del Módulo III", ""), IF(AND(AX8<>"", AX8>=40, COUNTA(AM8:AW8)=0), "⚠️Faltan notas del Módulo IV", ""), IF(AND(BJ8<>"", BJ8>=40, COUNTA(AY8:BI8)=0), "⚠️Faltan notas del Módulo V", ""), IF(AND(BV8<>"", BV8>=40, COUNTA(BK8:BU8)=0), "⚠️Faltan notas del Módulo VI", ""), IF(AND(CH8<>"", CH8>=40, COUNTA(BW8:CG8)=0), "⚠️Faltan notas del Módulo VII", ""), IF(AND(CT8<>"", CT8>=40, COUNTA(CI8:CS8)=0), "⚠️Faltan notas del Módulo VIII", ""), IF(AND(DF8<>"", DF8>=40, COUNTA(CU8:DE8)=0), "⚠️Faltan notas del Módulo IX", "") ) ) | FH8: {=IF( COUNT(DZ8:EH8)=0, "-", IF( COUNT(DZ8:EH8) < COUNTA(DZ8:EH8), REPT("🟩", ROUND(COUNT(DZ8:EH8)/COUNTA(DZ8:EH8)*5, 0)) & REPT("⬜", 5 - ROUND(COUNT(DZ8:EH8)/COUNTA(DZ8:EH8)*5, 0)), IF( AVERAGE(IF(DZ8:EH8<>"", DZ8:EH8, )) >= 70, "🟩🟩🟩🟩🟩", IF( AVERAGE(IF(DZ8:EH8<>"",DZ8:EH8, )) >= 56, "🟨🟨🟨🟨🟨", "🟥🟥🟥🟥🟥" ) ) ) )} -> -
N9: =IFERROR(SUM(DT9:DU9)/SUM($DT$7:$DU$7)*100,"") | Z9: =IFERROR(SUM(EB9:EC9)/SUM($EB$7:$EC$7)*100,"") | AL9: =IFERROR(SUM(EK9:EL9)/SUM($EK$7:$EL$7)*100,"") | AX9: =IFERROR(SUM(EW9:EY9)/SUM($EW$7:$EY$7)*100,"") | BJ9: =IFERROR(SUM(EZ9)/SUM($EZ$7)*100,"") | BV9: =IFERROR(SUM(FA9:FB9)/SUM($FA$7:$FB$7)*100,"") | CH9: =IFERROR(SUM(FC9:FD9)/SUM($FC$7:$FD$7)*100,"") | CT9: =IFERROR(SUM(FE9:FF9)/SUM($FE$7:$FF$7)*100,"") | DG9: {=IFERROR(_xlfn.XLOOKUP($A9&B9,MARZO!$D$11:$D$40&MARZO!$E$11:$E$40,MARZO!$AM$11:$AM$40,_xlfn.XLOOKUP($A9&$B9,MARZO!$BC$11:$BC$40&MARZO!$BD$11:$BD$40,MARZO!$CL$11:$CL$40,"A"))/1%,"")} | DH9: {=IFERROR(_xlfn.XLOOKUP($A9&$B9,ABRIL!$D$11:$D$40&ABRIL!$E$11:$E$40,ABRIL!$AM$11:$AM$40,_xlfn.XLOOKUP($A9&$B9,ABRIL!$BC$11:$BC$40&ABRIL!$BD$11:$BD$40,ABRIL!$CL$11:$CL$40,"A"))/1%,"")} | DI9: {=IFERROR(_xlfn.XLOOKUP($A9&$B9,'ABRIL 2'!$D$11:$D$40&'ABRIL 2'!$E$11:$E$40,'ABRIL 2'!$AM$11:$AM$40,_xlfn.XLOOKUP($A9&$B9,'ABRIL 2'!$BC$11:$BC$40&'ABRIL 2'!$BD$11:$BD$40,'ABRIL 2'!$CL$11:$CL$40,"A"))/1%,"")} | DJ9: {=IFERROR(_xlfn.XLOOKUP($A9&$B9,MAYO!$D$11:$D$40&MAYO!$E$11:$E$40,MAYO!$AM$11:$AM$40,_xlfn.XLOOKUP($A9&$B9,MAYO!$BC$11:$BC$40&MAYO!$BD$11:$BD$40,MAYO!$CL$11:$CL$40,"A"))/1%,"")} | DK9: {=IFERROR(_xlfn.XLOOKUP($A9&$B9,'MAYO 2'!$D$11:$D$40&'MAYO 2'!$E$11:$E$40,'MAYO 2'!$AM$11:$AM$40,_xlfn.XLOOKUP($A9&$B9,'MAYO 2'!$BC$11:$BC$40&'MAYO 2'!$BD$11:$BD$40,'MAYO 2'!$CL$11:$CL$40,"A"))/1%,"")} | DL9: {=IFERROR(_xlfn.XLOOKUP($A9&$B9,JUNIO!$D$11:$D$40&JUNIO!$E$11:$E$40,JUNIO!$AM$11:$AM$40,_xlfn.XLOOKUP($A9&$B9,JUNIO!$BC$11:$BC$40&JUNIO!$BD$11:$BD$40,JUNIO!$CL$11:$CL$40,"A"))/1%,"")} | DM9: {=IFERROR(_xlfn.XLOOKUP($A9&$B9,'JUNIO 2'!$D$11:$D$40&'JUNIO 2'!$E$11:$E$40,'JUNIO 2'!$AM$11:$AM$40,_xlfn.XLOOKUP($A9&$B9,'JUNIO 2'!$BC$11:$BC$40&'JUNIO 2'!$BD$11:$BD$40,'JUNIO 2'!$CL$11:$CL$40,"A"))/1%,"")} | DN9: {=IFERROR(_xlfn.XLOOKUP($A9&$B9,JULIO!$D$11:$D$40&JULIO!$E$11:$E$40,JULIO!$AM$11:$AM$40,_xlfn.XLOOKUP($A9&$B9,JULIO!$BC$11:$BC$40&JULIO!$BD$11:$BD$40,JULIO!$CL$11:$CL$40,"A"))/1%,"")} | DO9: {=IFERROR(_xlfn.XLOOKUP($A9&$B9,'JULIO 2'!$D$11:$D$40&'JULIO 2'!$E$11:$E$40,'JULIO 2'!$AM$11:$AM$40,_xlfn.XLOOKUP($A9&$B9,'JULIO 2'!$BC$11:$BC$40&'JULIO 2'!$BD$11:$BD$40,'JULIO 2'!$CL$11:$CL$40,"A"))/1%,"")} | DP9: {=IFERROR(_xlfn.XLOOKUP($A9&$B9,AGOSTO!$D$11:$D$40&AGOSTO!$E$11:$E$40,AGOSTO!$AM$11:$AM$40,_xlfn.XLOOKUP($A9&$B9,AGOSTO!$BC$11:$BC$40&AGOSTO!$BD$11:$BD$40,AGOSTO!$CL$11:$CL$40,"A"))/1%,"")} | DQ9: {=IFERROR(_xlfn.XLOOKUP($A9&$B9,'AGOSTO 2'!$D$11:$D$40&'AGOSTO 2'!$E$11:$E$40,'AGOSTO 2'!$AM$11:$AM$40,_xlfn.XLOOKUP($A9&$B9,'AGOSTO 2'!$BC$11:$BC$40&'AGOSTO 2'!$BD$11:$BD$40,'AGOSTO 2'!$CL$11:$CL$40,"A"))/1%,"")} | DR9: {=IFERROR(_xlfn.XLOOKUP($A9&$B9,SEPTIEMBRE!$D$11:$D$40&SEPTIEMBRE!$E$11:$E$40,SEPTIEMBRE!$AM$11:$AM$40,_xlfn.XLOOKUP($A9&$B9,SEPTIEMBRE!$BC$11:$BC$40&SEPTIEMBRE!$BD$11:$BD$40,SEPTIEMBRE!$CL$11:$CL$40,"A"))/1%,"")} | DS9: {=IFERROR(_xlfn.XLOOKUP($A9&$B9,'SEPTIEMBRE 2'!$D$11:$D$40&'SEPTIEMBRE 2'!$E$11:$E$40,'SEPTIEMBRE 2'!$AM$11:$AM$40,_xlfn.XLOOKUP($A9&$B9,'SEPTIEMBRE 2'!$BC$11:$BC$40&'SEPTIEMBRE 2'!$BD$11:$BD$40,'SEPTIEMBRE 2'!$CL$11:$CL$40,"A"))/1%,"")} | DT9: {=IFERROR(_xlfn.XLOOKUP($A9&$B9,'SEPTIEMBRE 3'!$D$11:$D$40&'SEPTIEMBRE 3'!$E$11:$E$40,'SEPTIEMBRE 3'!$AM$11:$AM$40,_xlfn.XLOOKUP($A9&$B9,'SEPTIEMBRE 3'!$BC$11:$BC$40&'SEPTIEMBRE 3'!$BD$11:$BD$40,'SEPTIEMBRE 3'!$CL$11:$CL$40,"A"))/1%,"")} | DU9: {=IFERROR(_xlfn.XLOOKUP($A9&$B9,OCTUBRE!$D$11:$D$40&OCTUBRE!$E$11:$E$40,OCTUBRE!$AM$11:$AM$40,_xlfn.XLOOKUP($A9&$B9,OCTUBRE!$BC$11:$BC$40&OCTUBRE!$BD$11:$BD$40,OCTUBRE!$CL$11:$CL$40,"A"))/1%,"")} | DV9: {=IFERROR(_xlfn.XLOOKUP($A9&$B9,'OCTUBRE 2'!$D$11:$D$40&'OCTUBRE 2'!$E$11:$E$40,'OCTUBRE 2'!$AM$11:$AM$40,_xlfn.XLOOKUP($A9&$B9,'OCTUBRE 2'!$BC$11:$BC$40&'OCTUBRE 2'!$BD$11:$BD$40,'OCTUBRE 2'!$CL$11:$CL$40,"A"))/1%,"")} | DW9: {=IFERROR(_xlfn.XLOOKUP($A9&$B9,NOVIEMBRE!$D$11:$D$40&NOVIEMBRE!$E$11:$E$40,NOVIEMBRE!$AM$11:$AM$40,_xlfn.XLOOKUP($A9&$B9,NOVIEMBRE!$BC$11:$BC$40&NOVIEMBRE!$BD$11:$BD$40,NOVIEMBRE!$CL$11:$CL$40,"A"))/1%,"")} | DX9: {=IFERROR(_xlfn.XLOOKUP($A9&$B9,'NOVIEMBRE 2'!$D$11:$D$40&'NOVIEMBRE 2'!$E$11:$E$40,'NOVIEMBRE 2'!$AM$11:$AM$40,_xlfn.XLOOKUP($A9&$B9,'NOVIEMBRE 2'!$BC$11:$BC$40&'NOVIEMBRE 2'!$BD$11:$BD$40,'NOVIEMBRE 2'!$CL$11:$CL$40,"A"))/1%,"")} | DY9: {=IFERROR(_xlfn.XLOOKUP($A9&$B9,DICIEMBRE!$D$11:$D$40&DICIEMBRE!$E$11:$E$40,DICIEMBRE!$AM$11:$AM$40,_xlfn.XLOOKUP($A9&$B9,DICIEMBRE!$BC$11:$BC$40&DICIEMBRE!$BD$11:$BD$40,DICIEMBRE!$CL$11:$CL$40,"A"))/1%,"")} | DZ9: =IFERROR(IF(COUNTIF(C9:N9,"-"),"A",ROUND(AVERAGE(C9:N9),0)),"-") -> - | EA9: =IFERROR(IF(COUNTIF(O9:Z9,"-"),"A",ROUND(AVERAGE(O9:Z9),0)),"-") -> - | EB9: =IFERROR(IF(COUNTIF(AA9:AL9,"-"),"A",ROUND(AVERAGE(AA9:AL9),0)),"-") -> - | EC9: =IFERROR(IF(COUNTIF(AM9:AX9,"-"),"A",ROUND(AVERAGE(AM9:AX9),0)),"-") -> - | ED9: =IFERROR(IF(COUNTIF(AY9:BJ9,"-"),"A",ROUND(AVERAGE(AY9:BJ9),0)),"-") -> - | EE9: =IFERROR(IF(COUNTIF(BK9:BV9,"-"),"A",ROUND(AVERAGE(BK9:BV9),0)),"-") -> - | EF9: =IFERROR(IF(COUNTIF(BW9:CH9,"-"),"A",ROUND(AVERAGE(BW9:CH9),0)),"-") -> - | EG9: =IFERROR(IF(COUNTIF(CI9:CT9,"-"),"A",ROUND(AVERAGE(CI9:CT9),0)),"-") -> - | EH9: =IFERROR(IF(COUNTIF(CU9:DF9,"-"),"A",ROUND(AVERAGE(CU9:DF9),0)),"-") -> - | EI9: =IFERROR(ROUND(AVERAGE(DZ9:EH9),0),"") | EN9: {=IFERROR(_xlfn.XLOOKUP($A9&$B9,MARZO!$D$11:$D$40&MARZO!$E$11:$E$40,MARZO!$AK$11:$AK$40,_xlfn.XLOOKUP($A9&$B9,MARZO!$BC$11:$BC$40&MARZO!$BD$11:$BD$40,MARZO!$CJ$11:$CJ$40,"A")),"")} -> 0 | EO9: {=IFERROR(_xlfn.XLOOKUP($A9&$B9,ABRIL!$D$11:$D$40&ABRIL!$E$11:$E$40,ABRIL!$AK$11:$AK$40,_xlfn.XLOOKUP($A9&$B9,ABRIL!$BC$11:$BC$40&ABRIL!$BD$11:$BD$40,ABRIL!$CJ$11:$CJ$40,"A")),"")} -> 0 | EP9: {=IFERROR(_xlfn.XLOOKUP($A9&$B9,'ABRIL 2'!$D$11:$D$40&'ABRIL 2'!$E$11:$E$40,'ABRIL 2'!$AK$11:$AK$40,_xlfn.XLOOKUP($A9&$B9,'ABRIL 2'!$BC$11:$BC$40&'ABRIL 2'!$BD$11:$BD$40,'ABRIL 2'!$CJ$11:$CJ$40,"A")),"")} -> 0 | EQ9: {=IFERROR(_xlfn.XLOOKUP($A9&$B9,MAYO!$D$11:$D$40&MAYO!$E$11:$E$40,MAYO!$AK$11:$AK$40,_xlfn.XLOOKUP($A9&$B9,MAYO!$BC$11:$BC$40&MAYO!$BD$11:$BD$40,MAYO!$CJ$11:$CJ$40,"A")),"")} -> 0 | ER9: {=IFERROR(_xlfn.XLOOKUP($A9&$B9,'MAYO 2'!$D$11:$D$40&'MAYO 2'!$E$11:$E$40,'MAYO 2'!$AK$11:$AK$40,_xlfn.XLOOKUP($A9&$B9,'MAYO 2'!$BC$11:$BC$40&'MAYO 2'!$BD$11:$BD$40,'MAYO 2'!$CJ$11:$CJ$40,"A")),"")} -> 0 | ES9: {=IFERROR(_xlfn.XLOOKUP($A9&$B9,JUNIO!$D$11:$D$40&JUNIO!$E$11:$E$40,JUNIO!$AK$11:$AK$40,_xlfn.XLOOKUP($A9&$B9,JUNIO!$BC$11:$BC$40&JUNIO!$BD$11:$BD$40,JUNIO!$CJ$11:$CJ$40,"A")),"")} -> 0 | ET9: {=IFERROR(_xlfn.XLOOKUP($A9&$B9,'JUNIO 2'!$D$11:$D$40&'JUNIO 2'!$E$11:$E$40,'JUNIO 2'!$AK$11:$AK$40,_xlfn.XLOOKUP($A9&$B9,'JUNIO 2'!$BC$11:$BC$40&'JUNIO 2'!$BD$11:$BD$40,'JUNIO 2'!$CJ$11:$CJ$40,"A")),"")} -> 0 | EU9: {=IFERROR(_xlfn.XLOOKUP($A9&$B9,JULIO!$D$11:$D$40&JULIO!$E$11:$E$40,JULIO!$AK$11:$AK$40,_xlfn.XLOOKUP($A9&$B9,JULIO!$BC$11:$BC$40&JULIO!$BD$11:$BD$40,JULIO!$CJ$11:$CJ$40,"A")),"")} -> 0 | EV9: {=IFERROR(_xlfn.XLOOKUP($A9&$B9,'JULIO 2'!$D$11:$D$40&'JULIO 2'!$E$11:$E$40,'JULIO 2'!$AK$11:$AK$40,_xlfn.XLOOKUP($A9&$B9,'JULIO 2'!$BC$11:$BC$40&'JULIO 2'!$BD$11:$BD$40,'JULIO 2'!$CJ$11:$CJ$40,"A")),"")} -> 0 | EW9: {=IFERROR(_xlfn.XLOOKUP($A9&$B9,AGOSTO!$D$11:$D$40&AGOSTO!$E$11:$E$40,AGOSTO!$AK$11:$AK$40,_xlfn.XLOOKUP($A9&$B9,AGOSTO!$BC$11:$BC$40&AGOSTO!$BD$11:$BD$40,AGOSTO!$CJ$11:$CJ$40,"A")),"")} -> 0 | EX9: {=IFERROR(_xlfn.XLOOKUP($A9&$B9,'AGOSTO 2'!$D$11:$D$40&'AGOSTO 2'!$E$11:$E$40,'AGOSTO 2'!$AK$11:$AK$40,_xlfn.XLOOKUP($A9&$B9,'AGOSTO 2'!$BC$11:$BC$40&'AGOSTO 2'!$BD$11:$BD$40,'AGOSTO 2'!$CJ$11:$CJ$40,"A")),"")} -> 0 | EY9: {=IFERROR(_xlfn.XLOOKUP($A9&$B9,SEPTIEMBRE!$D$11:$D$40&SEPTIEMBRE!$E$11:$E$40,SEPTIEMBRE!$AK$11:$AK$40,_xlfn.XLOOKUP($A9&$B9,SEPTIEMBRE!$BC$11:$BC$40&SEPTIEMBRE!$BD$11:$BD$40,SEPTIEMBRE!$CJ$11:$CJ$40,"A")),"")} -> 0 | EZ9: {=IFERROR(_xlfn.XLOOKUP($A9&$B9,'SEPTIEMBRE 2'!$D$11:$D$40&'SEPTIEMBRE 2'!$E$11:$E$40,'SEPTIEMBRE 2'!$AK$11:$AK$40,_xlfn.XLOOKUP($A9&$B9,'SEPTIEMBRE 2'!$BC$11:$BC$40&'SEPTIEMBRE 2'!$BD$11:$BD$40,'SEPTIEMBRE 2'!$CJ$11:$CJ$40,"A")),"")} -> 0 | FA9: {=IFERROR(_xlfn.XLOOKUP($A9&$B9,'SEPTIEMBRE 3'!$D$11:$D$40&'SEPTIEMBRE 3'!$E$11:$E$40,'SEPTIEMBRE 3'!$AK$11:$AK$40,_xlfn.XLOOKUP($A9&$B9,'SEPTIEMBRE 3'!$BC$11:$BC$40&'SEPTIEMBRE 3'!$BD$11:$BD$40,'SEPTIEMBRE 3'!$CJ$11:$CJ$40,"A")),"")} -> 0 | FB9: {=IFERROR(_xlfn.XLOOKUP($A9&$B9,OCTUBRE!$D$11:$D$40&OCTUBRE!$E$11:$E$40,OCTUBRE!$AK$11:$AK$40,_xlfn.XLOOKUP($A9&$B9,OCTUBRE!$BC$11:$BC$40&OCTUBRE!$BD$11:$BD$40,OCTUBRE!$CJ$11:$CJ$40,"A")),"")} -> 0 | FC9: {=IFERROR(_xlfn.XLOOKUP($A9&$B9,'OCTUBRE 2'!$D$11:$D$40&'OCTUBRE 2'!$E$11:$E$40,'OCTUBRE 2'!$AK$11:$AK$40,_xlfn.XLOOKUP($A9&$B9,'OCTUBRE 2'!$BC$11:$BC$40&'OCTUBRE 2'!$BD$11:$BD$40,'OCTUBRE 2'!$CJ$11:$CJ$40,"A")),"")} -> 0 | FD9: {=IFERROR(_xlfn.XLOOKUP($A9&$B9,NOVIEMBRE!$D$11:$D$40&NOVIEMBRE!$E$11:$E$40,NOVIEMBRE!$AK$11:$AK$40,_xlfn.XLOOKUP($A9&$B9,NOVIEMBRE!$BC$11:$BC$40&NOVIEMBRE!$BD$11:$BD$40,NOVIEMBRE!$CJ$11:$CJ$40,"A")),"")} -> 0 | FE9: {=IFERROR(_xlfn.XLOOKUP($A9&$B9,'NOVIEMBRE 2'!$D$11:$D$40&'NOVIEMBRE 2'!$E$11:$E$40,'NOVIEMBRE 2'!$AK$11:$AK$40,_xlfn.XLOOKUP($A9&$B9,'NOVIEMBRE 2'!$BC$11:$BC$40&'NOVIEMBRE 2'!$BD$11:$BD$40,'NOVIEMBRE 2'!$CJ$11:$CJ$40,"A")),"")} -> 0 | FF9: {=IFERROR(_xlfn.XLOOKUP($A9&$B9,DICIEMBRE!$D$11:$D$40&DICIEMBRE!$E$11:$E$40,DICIEMBRE!$AK$11:$AK$40,_xlfn.XLOOKUP($A9&$B9,DICIEMBRE!$BC$11:$BC$40&DICIEMBRE!$BD$11:$BD$40,DICIEMBRE!$CJ$11:$CJ$40,"A")),"")} -> 0 | FG9: =IF( AND(N9="", Z9="", AL9="", AX9="", BJ9="", BV9="", CH9="", CT9="",DF9=""), "", TEXTJOIN( " ", TRUE, IF(AND(N9<>"", N9>=40, COUNTA(C9:M9)=0), "⚠️Faltan notas del Módulo I", ""), IF(AND(Z9<>"", Z9>=40, COUNTA(O9:Y9)=0), "⚠️Faltan notas del Módulo II", ""), IF(AND(AL9<>"", AL9>=40, COUNTA(AA9:AK9)=0), "⚠️Faltan notas del Módulo III", ""), IF(AND(AX9<>"", AX9>=40, COUNTA(AM9:AW9)=0), "⚠️Faltan notas del Módulo IV", ""), IF(AND(BJ9<>"", BJ9>=40, COUNTA(AY9:BI9)=0), "⚠️Faltan notas del Módulo V", ""), IF(AND(BV9<>"", BV9>=40, COUNTA(BK9:BU9)=0), "⚠️Faltan notas del Módulo VI", ""), IF(AND(CH9<>"", CH9>=40, COUNTA(BW9:CG9)=0), "⚠️Faltan notas del Módulo VII", ""), IF(AND(CT9<>"", CT9>=40, COUNTA(CI9:CS9)=0), "⚠️Faltan notas del Módulo VIII", ""), IF(AND(DF9<>"", DF9>=40, COUNTA(CU9:DE9)=0), "⚠️Faltan notas del Módulo IX", "") ) ) | FH9: {=IF( COUNT(DZ9:EH9)=0, "-", IF( COUNT(DZ9:EH9) < COUNTA(DZ9:EH9), REPT("🟩", ROUND(COUNT(DZ9:EH9)/COUNTA(DZ9:EH9)*5, 0)) & REPT("⬜", 5 - ROUND(COUNT(DZ9:EH9)/COUNTA(DZ9:EH9)*5, 0)), IF( AVERAGE(IF(DZ9:EH9<>"", DZ9:EH9, )) >= 70, "🟩🟩🟩🟩🟩", IF( AVERAGE(IF(DZ9:EH9<>"",DZ9:EH9, )) >= 56, "🟨🟨🟨🟨🟨", "🟥🟥🟥🟥🟥" ) ) ) )} -> -
N10: =IFERROR(SUM(DT10:DU10)/SUM($DT$7:$DU$7)*100,"") | Z10: =IFERROR(SUM(EB10:EC10)/SUM($EB$7:$EC$7)*100,"") | AL10: =IFERROR(SUM(EK10:EL10)/SUM($EK$7:$EL$7)*100,"") | AX10: =IFERROR(SUM(EW10:EY10)/SUM($EW$7:$EY$7)*100,"") | BJ10: =IFERROR(SUM(EZ10)/SUM($EZ$7)*100,"") | BV10: =IFERROR(SUM(FA10:FB10)/SUM($FA$7:$FB$7)*100,"") | CH10: =IFERROR(SUM(FC10:FD10)/SUM($FC$7:$FD$7)*100,"") | CT10: =IFERROR(SUM(FE10:FF10)/SUM($FE$7:$FF$7)*100,"") | DG10: {=IFERROR(_xlfn.XLOOKUP($A10&B10,MARZO!$D$11:$D$40&MARZO!$E$11:$E$40,MARZO!$AM$11:$AM$40,_xlfn.XLOOKUP($A10&$B10,MARZO!$BC$11:$BC$40&MARZO!$BD$11:$BD$40,MARZO!$CL$11:$CL$40,"A"))/1%,"")} | DH10: {=IFERROR(_xlfn.XLOOKUP($A10&$B10,ABRIL!$D$11:$D$40&ABRIL!$E$11:$E$40,ABRIL!$AM$11:$AM$40,_xlfn.XLOOKUP($A10&$B10,ABRIL!$BC$11:$BC$40&ABRIL!$BD$11:$BD$40,ABRIL!$CL$11:$CL$40,"A"))/1%,"")} | DI10: {=IFERROR(_xlfn.XLOOKUP($A10&$B10,'ABRIL 2'!$D$11:$D$40&'ABRIL 2'!$E$11:$E$40,'ABRIL 2'!$AM$11:$AM$40,_xlfn.XLOOKUP($A10&$B10,'ABRIL 2'!$BC$11:$BC$40&'ABRIL 2'!$BD$11:$BD$40,'ABRIL 2'!$CL$11:$CL$40,"A"))/1%,"")} | DJ10: {=IFERROR(_xlfn.XLOOKUP($A10&$B10,MAYO!$D$11:$D$40&MAYO!$E$11:$E$40,MAYO!$AM$11:$AM$40,_xlfn.XLOOKUP($A10&$B10,MAYO!$BC$11:$BC$40&MAYO!$BD$11:$BD$40,MAYO!$CL$11:$CL$40,"A"))/1%,"")} | DK10: {=IFERROR(_xlfn.XLOOKUP($A10&$B10,'MAYO 2'!$D$11:$D$40&'MAYO 2'!$E$11:$E$40,'MAYO 2'!$AM$11:$AM$40,_xlfn.XLOOKUP($A10&$B10,'MAYO 2'!$BC$11:$BC$40&'MAYO 2'!$BD$11:$BD$40,'MAYO 2'!$CL$11:$CL$40,"A"))/1%,"")} | DL10: {=IFERROR(_xlfn.XLOOKUP($A10&$B10,JUNIO!$D$11:$D$40&JUNIO!$E$11:$E$40,JUNIO!$AM$11:$AM$40,_xlfn.XLOOKUP($A10&$B10,JUNIO!$BC$11:$BC$40&JUNIO!$BD$11:$BD$40,JUNIO!$CL$11:$CL$40,"A"))/1%,"")} | DM10: {=IFERROR(_xlfn.XLOOKUP($A10&$B10,'JUNIO 2'!$D$11:$D$40&'JUNIO 2'!$E$11:$E$40,'JUNIO 2'!$AM$11:$AM$40,_xlfn.XLOOKUP($A10&$B10,'JUNIO 2'!$BC$11:$BC$40&'JUNIO 2'!$BD$11:$BD$40,'JUNIO 2'!$CL$11:$CL$40,"A"))/1%,"")} | DN10: {=IFERROR(_xlfn.XLOOKUP($A10&$B10,JULIO!$D$11:$D$40&JULIO!$E$11:$E$40,JULIO!$AM$11:$AM$40,_xlfn.XLOOKUP($A10&$B10,JULIO!$BC$11:$BC$40&JULIO!$BD$11:$BD$40,JULIO!$CL$11:$CL$40,"A"))/1%,"")} | DO10: {=IFERROR(_xlfn.XLOOKUP($A10&$B10,'JULIO 2'!$D$11:$D$40&'JULIO 2'!$E$11:$E$40,'JULIO 2'!$AM$11:$AM$40,_xlfn.XLOOKUP($A10&$B10,'JULIO 2'!$BC$11:$BC$40&'JULIO 2'!$BD$11:$BD$40,'JULIO 2'!$CL$11:$CL$40,"A"))/1%,"")} | DP10: {=IFERROR(_xlfn.XLOOKUP($A10&$B10,AGOSTO!$D$11:$D$40&AGOSTO!$E$11:$E$40,AGOSTO!$AM$11:$AM$40,_xlfn.XLOOKUP($A10&$B10,AGOSTO!$BC$11:$BC$40&AGOSTO!$BD$11:$BD$40,AGOSTO!$CL$11:$CL$40,"A"))/1%,"")} | DQ10: {=IFERROR(_xlfn.XLOOKUP($A10&$B10,'AGOSTO 2'!$D$11:$D$40&'AGOSTO 2'!$E$11:$E$40,'AGOSTO 2'!$AM$11:$AM$40,_xlfn.XLOOKUP($A10&$B10,'AGOSTO 2'!$BC$11:$BC$40&'AGOSTO 2'!$BD$11:$BD$40,'AGOSTO 2'!$CL$11:$CL$40,"A"))/1%,"")} | DR10: {=IFERROR(_xlfn.XLOOKUP($A10&$B10,SEPTIEMBRE!$D$11:$D$40&SEPTIEMBRE!$E$11:$E$40,SEPTIEMBRE!$AM$11:$AM$40,_xlfn.XLOOKUP($A10&$B10,SEPTIEMBRE!$BC$11:$BC$40&SEPTIEMBRE!$BD$11:$BD$40,SEPTIEMBRE!$CL$11:$CL$40,"A"))/1%,"")} | DS10: {=IFERROR(_xlfn.XLOOKUP($A10&$B10,'SEPTIEMBRE 2'!$D$11:$D$40&'SEPTIEMBRE 2'!$E$11:$E$40,'SEPTIEMBRE 2'!$AM$11:$AM$40,_xlfn.XLOOKUP($A10&$B10,'SEPTIEMBRE 2'!$BC$11:$BC$40&'SEPTIEMBRE 2'!$BD$11:$BD$40,'SEPTIEMBRE 2'!$CL$11:$CL$40,"A"))/1%,"")} | DT10: {=IFERROR(_xlfn.XLOOKUP($A10&$B10,'SEPTIEMBRE 3'!$D$11:$D$40&'SEPTIEMBRE 3'!$E$11:$E$40,'SEPTIEMBRE 3'!$AM$11:$AM$40,_xlfn.XLOOKUP($A10&$B10,'SEPTIEMBRE 3'!$BC$11:$BC$40&'SEPTIEMBRE 3'!$BD$11:$BD$40,'SEPTIEMBRE 3'!$CL$11:$CL$40,"A"))/1%,"")} | DU10: {=IFERROR(_xlfn.XLOOKUP($A10&$B10,OCTUBRE!$D$11:$D$40&OCTUBRE!$E$11:$E$40,OCTUBRE!$AM$11:$AM$40,_xlfn.XLOOKUP($A10&$B10,OCTUBRE!$BC$11:$BC$40&OCTUBRE!$BD$11:$BD$40,OCTUBRE!$CL$11:$CL$40,"A"))/1%,"")} | DV10: {=IFERROR(_xlfn.XLOOKUP($A10&$B10,'OCTUBRE 2'!$D$11:$D$40&'OCTUBRE 2'!$E$11:$E$40,'OCTUBRE 2'!$AM$11:$AM$40,_xlfn.XLOOKUP($A10&$B10,'OCTUBRE 2'!$BC$11:$BC$40&'OCTUBRE 2'!$BD$11:$BD$40,'OCTUBRE 2'!$CL$11:$CL$40,"A"))/1%,"")} | DW10: {=IFERROR(_xlfn.XLOOKUP($A10&$B10,NOVIEMBRE!$D$11:$D$40&NOVIEMBRE!$E$11:$E$40,NOVIEMBRE!$AM$11:$AM$40,_xlfn.XLOOKUP($A10&$B10,NOVIEMBRE!$BC$11:$BC$40&NOVIEMBRE!$BD$11:$BD$40,NOVIEMBRE!$CL$11:$CL$40,"A"))/1%,"")} | DX10: {=IFERROR(_xlfn.XLOOKUP($A10&$B10,'NOVIEMBRE 2'!$D$11:$D$40&'NOVIEMBRE 2'!$E$11:$E$40,'NOVIEMBRE 2'!$AM$11:$AM$40,_xlfn.XLOOKUP($A10&$B10,'NOVIEMBRE 2'!$BC$11:$BC$40&'NOVIEMBRE 2'!$BD$11:$BD$40,'NOVIEMBRE 2'!$CL$11:$CL$40,"A"))/1%,"")} | DY10: {=IFERROR(_xlfn.XLOOKUP($A10&$B10,DICIEMBRE!$D$11:$D$40&DICIEMBRE!$E$11:$E$40,DICIEMBRE!$AM$11:$AM$40,_xlfn.XLOOKUP($A10&$B10,DICIEMBRE!$BC$11:$BC$40&DICIEMBRE!$BD$11:$BD$40,DICIEMBRE!$CL$11:$CL$40,"A"))/1%,"")} | DZ10: =IFERROR(IF(COUNTIF(C10:N10,"-"),"A",ROUND(AVERAGE(C10:N10),0)),"-") -> - | EA10: =IFERROR(IF(COUNTIF(O10:Z10,"-"),"A",ROUND(AVERAGE(O10:Z10),0)),"-") -> - | EB10: =IFERROR(IF(COUNTIF(AA10:AL10,"-"),"A",ROUND(AVERAGE(AA10:AL10),0)),"-") -> - | EC10: =IFERROR(IF(COUNTIF(AM10:AX10,"-"),"A",ROUND(AVERAGE(AM10:AX10),0)),"-") -> - | ED10: =IFERROR(IF(COUNTIF(AY10:BJ10,"-"),"A",ROUND(AVERAGE(AY10:BJ10),0)),"-") -> - | EE10: =IFERROR(IF(COUNTIF(BK10:BV10,"-"),"A",ROUND(AVERAGE(BK10:BV10),0)),"-") -> - | EF10: =IFERROR(IF(COUNTIF(BW10:CH10,"-"),"A",ROUND(AVERAGE(BW10:CH10),0)),"-") -> - | EG10: =IFERROR(IF(COUNTIF(CI10:CT10,"-"),"A",ROUND(AVERAGE(CI10:CT10),0)),"-") -> - | EH10: =IFERROR(IF(COUNTIF(CU10:DF10,"-"),"A",ROUND(AVERAGE(CU10:DF10),0)),"-") -> - | EI10: =IFERROR(ROUND(AVERAGE(DZ10:EH10),0),"") | EN10: {=IFERROR(_xlfn.XLOOKUP($A10&$B10,MARZO!$D$11:$D$40&MARZO!$E$11:$E$40,MARZO!$AK$11:$AK$40,_xlfn.XLOOKUP($A10&$B10,MARZO!$BC$11:$BC$40&MARZO!$BD$11:$BD$40,MARZO!$CJ$11:$CJ$40,"A")),"")} -> 0 | EO10: {=IFERROR(_xlfn.XLOOKUP($A10&$B10,ABRIL!$D$11:$D$40&ABRIL!$E$11:$E$40,ABRIL!$AK$11:$AK$40,_xlfn.XLOOKUP($A10&$B10,ABRIL!$BC$11:$BC$40&ABRIL!$BD$11:$BD$40,ABRIL!$CJ$11:$CJ$40,"A")),"")} -> 0 | EP10: {=IFERROR(_xlfn.XLOOKUP($A10&$B10,'ABRIL 2'!$D$11:$D$40&'ABRIL 2'!$E$11:$E$40,'ABRIL 2'!$AK$11:$AK$40,_xlfn.XLOOKUP($A10&$B10,'ABRIL 2'!$BC$11:$BC$40&'ABRIL 2'!$BD$11:$BD$40,'ABRIL 2'!$CJ$11:$CJ$40,"A")),"")} -> 0 | EQ10: {=IFERROR(_xlfn.XLOOKUP($A10&$B10,MAYO!$D$11:$D$40&MAYO!$E$11:$E$40,MAYO!$AK$11:$AK$40,_xlfn.XLOOKUP($A10&$B10,MAYO!$BC$11:$BC$40&MAYO!$BD$11:$BD$40,MAYO!$CJ$11:$CJ$40,"A")),"")} -> 0 | ER10: {=IFERROR(_xlfn.XLOOKUP($A10&$B10,'MAYO 2'!$D$11:$D$40&'MAYO 2'!$E$11:$E$40,'MAYO 2'!$AK$11:$AK$40,_xlfn.XLOOKUP($A10&$B10,'MAYO 2'!$BC$11:$BC$40&'MAYO 2'!$BD$11:$BD$40,'MAYO 2'!$CJ$11:$CJ$40,"A")),"")} -> 0 | ES10: {=IFERROR(_xlfn.XLOOKUP($A10&$B10,JUNIO!$D$11:$D$40&JUNIO!$E$11:$E$40,JUNIO!$AK$11:$AK$40,_xlfn.XLOOKUP($A10&$B10,JUNIO!$BC$11:$BC$40&JUNIO!$BD$11:$BD$40,JUNIO!$CJ$11:$CJ$40,"A")),"")} -> 0 | ET10: {=IFERROR(_xlfn.XLOOKUP($A10&$B10,'JUNIO 2'!$D$11:$D$40&'JUNIO 2'!$E$11:$E$40,'JUNIO 2'!$AK$11:$AK$40,_xlfn.XLOOKUP($A10&$B10,'JUNIO 2'!$BC$11:$BC$40&'JUNIO 2'!$BD$11:$BD$40,'JUNIO 2'!$CJ$11:$CJ$40,"A")),"")} -> 0 | EU10: {=IFERROR(_xlfn.XLOOKUP($A10&$B10,JULIO!$D$11:$D$40&JULIO!$E$11:$E$40,JULIO!$AK$11:$AK$40,_xlfn.XLOOKUP($A10&$B10,JULIO!$BC$11:$BC$40&JULIO!$BD$11:$BD$40,JULIO!$CJ$11:$CJ$40,"A")),"")} -> 0 | EV10: {=IFERROR(_xlfn.XLOOKUP($A10&$B10,'JULIO 2'!$D$11:$D$40&'JULIO 2'!$E$11:$E$40,'JULIO 2'!$AK$11:$AK$40,_xlfn.XLOOKUP($A10&$B10,'JULIO 2'!$BC$11:$BC$40&'JULIO 2'!$BD$11:$BD$40,'JULIO 2'!$CJ$11:$CJ$40,"A")),"")} -> 0 | EW10: {=IFERROR(_xlfn.XLOOKUP($A10&$B10,AGOSTO!$D$11:$D$40&AGOSTO!$E$11:$E$40,AGOSTO!$AK$11:$AK$40,_xlfn.XLOOKUP($A10&$B10,AGOSTO!$BC$11:$BC$40&AGOSTO!$BD$11:$BD$40,AGOSTO!$CJ$11:$CJ$40,"A")),"")} -> 0 | EX10: {=IFERROR(_xlfn.XLOOKUP($A10&$B10,'AGOSTO 2'!$D$11:$D$40&'AGOSTO 2'!$E$11:$E$40,'AGOSTO 2'!$AK$11:$AK$40,_xlfn.XLOOKUP($A10&$B10,'AGOSTO 2'!$BC$11:$BC$40&'AGOSTO 2'!$BD$11:$BD$40,'AGOSTO 2'!$CJ$11:$CJ$40,"A")),"")} -> 0 | EY10: {=IFERROR(_xlfn.XLOOKUP($A10&$B10,SEPTIEMBRE!$D$11:$D$40&SEPTIEMBRE!$E$11:$E$40,SEPTIEMBRE!$AK$11:$AK$40,_xlfn.XLOOKUP($A10&$B10,SEPTIEMBRE!$BC$11:$BC$40&SEPTIEMBRE!$BD$11:$BD$40,SEPTIEMBRE!$CJ$11:$CJ$40,"A")),"")} -> 0 | EZ10: {=IFERROR(_xlfn.XLOOKUP($A10&$B10,'SEPTIEMBRE 2'!$D$11:$D$40&'SEPTIEMBRE 2'!$E$11:$E$40,'SEPTIEMBRE 2'!$AK$11:$AK$40,_xlfn.XLOOKUP($A10&$B10,'SEPTIEMBRE 2'!$BC$11:$BC$40&'SEPTIEMBRE 2'!$BD$11:$BD$40,'SEPTIEMBRE 2'!$CJ$11:$CJ$40,"A")),"")} -> 0 | FA10: {=IFERROR(_xlfn.XLOOKUP($A10&$B10,'SEPTIEMBRE 3'!$D$11:$D$40&'SEPTIEMBRE 3'!$E$11:$E$40,'SEPTIEMBRE 3'!$AK$11:$AK$40,_xlfn.XLOOKUP($A10&$B10,'SEPTIEMBRE 3'!$BC$11:$BC$40&'SEPTIEMBRE 3'!$BD$11:$BD$40,'SEPTIEMBRE 3'!$CJ$11:$CJ$40,"A")),"")} -> 0 | FB10: {=IFERROR(_xlfn.XLOOKUP($A10&$B10,OCTUBRE!$D$11:$D$40&OCTUBRE!$E$11:$E$40,OCTUBRE!$AK$11:$AK$40,_xlfn.XLOOKUP($A10&$B10,OCTUBRE!$BC$11:$BC$40&OCTUBRE!$BD$11:$BD$40,OCTUBRE!$CJ$11:$CJ$40,"A")),"")} -> 0 | FC10: {=IFERROR(_xlfn.XLOOKUP($A10&$B10,'OCTUBRE 2'!$D$11:$D$40&'OCTUBRE 2'!$E$11:$E$40,'OCTUBRE 2'!$AK$11:$AK$40,_xlfn.XLOOKUP($A10&$B10,'OCTUBRE 2'!$BC$11:$BC$40&'OCTUBRE 2'!$BD$11:$BD$40,'OCTUBRE 2'!$CJ$11:$CJ$40,"A")),"")} -> 0 | FD10: {=IFERROR(_xlfn.XLOOKUP($A10&$B10,NOVIEMBRE!$D$11:$D$40&NOVIEMBRE!$E$11:$E$40,NOVIEMBRE!$AK$11:$AK$40,_xlfn.XLOOKUP($A10&$B10,NOVIEMBRE!$BC$11:$BC$40&NOVIEMBRE!$BD$11:$BD$40,NOVIEMBRE!$CJ$11:$CJ$40,"A")),"")} -> 0 | FE10: {=IFERROR(_xlfn.XLOOKUP($A10&$B10,'NOVIEMBRE 2'!$D$11:$D$40&'NOVIEMBRE 2'!$E$11:$E$40,'NOVIEMBRE 2'!$AK$11:$AK$40,_xlfn.XLOOKUP($A10&$B10,'NOVIEMBRE 2'!$BC$11:$BC$40&'NOVIEMBRE 2'!$BD$11:$BD$40,'NOVIEMBRE 2'!$CJ$11:$CJ$40,"A")),"")} -> 0 | FF10: {=IFERROR(_xlfn.XLOOKUP($A10&$B10,DICIEMBRE!$D$11:$D$40&DICIEMBRE!$E$11:$E$40,DICIEMBRE!$AK$11:$AK$40,_xlfn.XLOOKUP($A10&$B10,DICIEMBRE!$BC$11:$BC$40&DICIEMBRE!$BD$11:$BD$40,DICIEMBRE!$CJ$11:$CJ$40,"A")),"")} -> 0 | FG10: =IF( AND(N10="", Z10="", AL10="", AX10="", BJ10="", BV10="", CH10="", CT10="",DF10=""), "", TEXTJOIN( " ", TRUE, IF(AND(N10<>"", N10>=40, COUNTA(C10:M10)=0), "⚠️Faltan notas del Módulo I", ""), IF(AND(Z10<>"", Z10>=40, COUNTA(O10:Y10)=0), "⚠️Faltan notas del Módulo II", ""), IF(AND(AL10<>"", AL10>=40, COUNTA(AA10:AK10)=0), "⚠️Faltan notas del Módulo III", ""), IF(AND(AX10<>"", AX10>=40, COUNTA(AM10:AW10)=0), "⚠️Faltan notas del Módulo IV", ""), IF(AND(BJ10<>"", BJ10>=40, COUNTA(AY10:BI10)=0), "⚠️Faltan notas del Módulo V", ""), IF(AND(BV10<>"", BV10>=40, COUNTA(BK10:BU10)=0), "⚠️Faltan notas del Módulo VI", ""), IF(AND(CH10<>"", CH10>=40, COUNTA(BW10:CG10)=0), "⚠️Faltan notas del Módulo VII", ""), IF(AND(CT10<>"", CT10>=40, COUNTA(CI10:CS10)=0), "⚠️Faltan notas del Módulo VIII", ""), IF(AND(DF10<>"", DF10>=40, COUNTA(CU10:DE10)=0), "⚠️Faltan notas del Módulo IX", "") ) ) | FH10: {=IF( COUNT(DZ10:EH10)=0, "-", IF( COUNT(DZ10:EH10) < COUNTA(DZ10:EH10), REPT("🟩", ROUND(COUNT(DZ10:EH10)/COUNTA(DZ10:EH10)*5, 0)) & REPT("⬜", 5 - ROUND(COUNT(DZ10:EH10)/COUNTA(DZ10:EH10)*5, 0)), IF( AVERAGE(IF(DZ10:EH10<>"", DZ10:EH10, )) >= 70, "🟩🟩🟩🟩🟩", IF( AVERAGE(IF(DZ10:EH10<>"",DZ10:EH10, )) >= 56, "🟨🟨🟨🟨🟨", "🟥🟥🟥🟥🟥" ) ) ) )} -> -
N11: =IFERROR(SUM(DT11:DU11)/SUM($DT$7:$DU$7)*100,"") | Z11: =IFERROR(SUM(EB11:EC11)/SUM($EB$7:$EC$7)*100,"") | AL11: =IFERROR(SUM(EK11:EL11)/SUM($EK$7:$EL$7)*100,"") | AX11: =IFERROR(SUM(EW11:EY11)/SUM($EW$7:$EY$7)*100,"") | BJ11: =IFERROR(SUM(EZ11)/SUM($EZ$7)*100,"") | BV11: =IFERROR(SUM(FA11:FB11)/SUM($FA$7:$FB$7)*100,"") | CH11: =IFERROR(SUM(FC11:FD11)/SUM($FC$7:$FD$7)*100,"") | CT11: =IFERROR(SUM(FE11:FF11)/SUM($FE$7:$FF$7)*100,"") | DG11: {=IFERROR(_xlfn.XLOOKUP($A11&B11,MARZO!$D$11:$D$40&MARZO!$E$11:$E$40,MARZO!$AM$11:$AM$40,_xlfn.XLOOKUP($A11&$B11,MARZO!$BC$11:$BC$40&MARZO!$BD$11:$BD$40,MARZO!$CL$11:$CL$40,"A"))/1%,"")} | DH11: {=IFERROR(_xlfn.XLOOKUP($A11&$B11,ABRIL!$D$11:$D$40&ABRIL!$E$11:$E$40,ABRIL!$AM$11:$AM$40,_xlfn.XLOOKUP($A11&$B11,ABRIL!$BC$11:$BC$40&ABRIL!$BD$11:$BD$40,ABRIL!$CL$11:$CL$40,"A"))/1%,"")} | DI11: {=IFERROR(_xlfn.XLOOKUP($A11&$B11,'ABRIL 2'!$D$11:$D$40&'ABRIL 2'!$E$11:$E$40,'ABRIL 2'!$AM$11:$AM$40,_xlfn.XLOOKUP($A11&$B11,'ABRIL 2'!$BC$11:$BC$40&'ABRIL 2'!$BD$11:$BD$40,'ABRIL 2'!$CL$11:$CL$40,"A"))/1%,"")} | DJ11: {=IFERROR(_xlfn.XLOOKUP($A11&$B11,MAYO!$D$11:$D$40&MAYO!$E$11:$E$40,MAYO!$AM$11:$AM$40,_xlfn.XLOOKUP($A11&$B11,MAYO!$BC$11:$BC$40&MAYO!$BD$11:$BD$40,MAYO!$CL$11:$CL$40,"A"))/1%,"")} | DK11: {=IFERROR(_xlfn.XLOOKUP($A11&$B11,'MAYO 2'!$D$11:$D$40&'MAYO 2'!$E$11:$E$40,'MAYO 2'!$AM$11:$AM$40,_xlfn.XLOOKUP($A11&$B11,'MAYO 2'!$BC$11:$BC$40&'MAYO 2'!$BD$11:$BD$40,'MAYO 2'!$CL$11:$CL$40,"A"))/1%,"")} | DL11: {=IFERROR(_xlfn.XLOOKUP($A11&$B11,JUNIO!$D$11:$D$40&JUNIO!$E$11:$E$40,JUNIO!$AM$11:$AM$40,_xlfn.XLOOKUP($A11&$B11,JUNIO!$BC$11:$BC$40&JUNIO!$BD$11:$BD$40,JUNIO!$CL$11:$CL$40,"A"))/1%,"")} | DM11: {=IFERROR(_xlfn.XLOOKUP($A11&$B11,'JUNIO 2'!$D$11:$D$40&'JUNIO 2'!$E$11:$E$40,'JUNIO 2'!$AM$11:$AM$40,_xlfn.XLOOKUP($A11&$B11,'JUNIO 2'!$BC$11:$BC$40&'JUNIO 2'!$BD$11:$BD$40,'JUNIO 2'!$CL$11:$CL$40,"A"))/1%,"")} | DN11: {=IFERROR(_xlfn.XLOOKUP($A11&$B11,JULIO!$D$11:$D$40&JULIO!$E$11:$E$40,JULIO!$AM$11:$AM$40,_xlfn.XLOOKUP($A11&$B11,JULIO!$BC$11:$BC$40&JULIO!$BD$11:$BD$40,JULIO!$CL$11:$CL$40,"A"))/1%,"")} | DO11: {=IFERROR(_xlfn.XLOOKUP($A11&$B11,'JULIO 2'!$D$11:$D$40&'JULIO 2'!$E$11:$E$40,'JULIO 2'!$AM$11:$AM$40,_xlfn.XLOOKUP($A11&$B11,'JULIO 2'!$BC$11:$BC$40&'JULIO 2'!$BD$11:$BD$40,'JULIO 2'!$CL$11:$CL$40,"A"))/1%,"")} | DP11: {=IFERROR(_xlfn.XLOOKUP($A11&$B11,AGOSTO!$D$11:$D$40&AGOSTO!$E$11:$E$40,AGOSTO!$AM$11:$AM$40,_xlfn.XLOOKUP($A11&$B11,AGOSTO!$BC$11:$BC$40&AGOSTO!$BD$11:$BD$40,AGOSTO!$CL$11:$CL$40,"A"))/1%,"")} | DQ11: {=IFERROR(_xlfn.XLOOKUP($A11&$B11,'AGOSTO 2'!$D$11:$D$40&'AGOSTO 2'!$E$11:$E$40,'AGOSTO 2'!$AM$11:$AM$40,_xlfn.XLOOKUP($A11&$B11,'AGOSTO 2'!$BC$11:$BC$40&'AGOSTO 2'!$BD$11:$BD$40,'AGOSTO 2'!$CL$11:$CL$40,"A"))/1%,"")} | DR11: {=IFERROR(_xlfn.XLOOKUP($A11&$B11,SEPTIEMBRE!$D$11:$D$40&SEPTIEMBRE!$E$11:$E$40,SEPTIEMBRE!$AM$11:$AM$40,_xlfn.XLOOKUP($A11&$B11,SEPTIEMBRE!$BC$11:$BC$40&SEPTIEMBRE!$BD$11:$BD$40,SEPTIEMBRE!$CL$11:$CL$40,"A"))/1%,"")} | DS11: {=IFERROR(_xlfn.XLOOKUP($A11&$B11,'SEPTIEMBRE 2'!$D$11:$D$40&'SEPTIEMBRE 2'!$E$11:$E$40,'SEPTIEMBRE 2'!$AM$11:$AM$40,_xlfn.XLOOKUP($A11&$B11,'SEPTIEMBRE 2'!$BC$11:$BC$40&'SEPTIEMBRE 2'!$BD$11:$BD$40,'SEPTIEMBRE 2'!$CL$11:$CL$40,"A"))/1%,"")} | DT11: {=IFERROR(_xlfn.XLOOKUP($A11&$B11,'SEPTIEMBRE 3'!$D$11:$D$40&'SEPTIEMBRE 3'!$E$11:$E$40,'SEPTIEMBRE 3'!$AM$11:$AM$40,_xlfn.XLOOKUP($A11&$B11,'SEPTIEMBRE 3'!$BC$11:$BC$40&'SEPTIEMBRE 3'!$BD$11:$BD$40,'SEPTIEMBRE 3'!$CL$11:$CL$40,"A"))/1%,"")} | DU11: {=IFERROR(_xlfn.XLOOKUP($A11&$B11,OCTUBRE!$D$11:$D$40&OCTUBRE!$E$11:$E$40,OCTUBRE!$AM$11:$AM$40,_xlfn.XLOOKUP($A11&$B11,OCTUBRE!$BC$11:$BC$40&OCTUBRE!$BD$11:$BD$40,OCTUBRE!$CL$11:$CL$40,"A"))/1%,"")} | DV11: {=IFERROR(_xlfn.XLOOKUP($A11&$B11,'OCTUBRE 2'!$D$11:$D$40&'OCTUBRE 2'!$E$11:$E$40,'OCTUBRE 2'!$AM$11:$AM$40,_xlfn.XLOOKUP($A11&$B11,'OCTUBRE 2'!$BC$11:$BC$40&'OCTUBRE 2'!$BD$11:$BD$40,'OCTUBRE 2'!$CL$11:$CL$40,"A"))/1%,"")} | DW11: {=IFERROR(_xlfn.XLOOKUP($A11&$B11,NOVIEMBRE!$D$11:$D$40&NOVIEMBRE!$E$11:$E$40,NOVIEMBRE!$AM$11:$AM$40,_xlfn.XLOOKUP($A11&$B11,NOVIEMBRE!$BC$11:$BC$40&NOVIEMBRE!$BD$11:$BD$40,NOVIEMBRE!$CL$11:$CL$40,"A"))/1%,"")} | DX11: {=IFERROR(_xlfn.XLOOKUP($A11&$B11,'NOVIEMBRE 2'!$D$11:$D$40&'NOVIEMBRE 2'!$E$11:$E$40,'NOVIEMBRE 2'!$AM$11:$AM$40,_xlfn.XLOOKUP($A11&$B11,'NOVIEMBRE 2'!$BC$11:$BC$40&'NOVIEMBRE 2'!$BD$11:$BD$40,'NOVIEMBRE 2'!$CL$11:$CL$40,"A"))/1%,"")} | DY11: {=IFERROR(_xlfn.XLOOKUP($A11&$B11,DICIEMBRE!$D$11:$D$40&DICIEMBRE!$E$11:$E$40,DICIEMBRE!$AM$11:$AM$40,_xlfn.XLOOKUP($A11&$B11,DICIEMBRE!$BC$11:$BC$40&DICIEMBRE!$BD$11:$BD$40,DICIEMBRE!$CL$11:$CL$40,"A"))/1%,"")} | DZ11: =IFERROR(IF(COUNTIF(C11:N11,"-"),"A",ROUND(AVERAGE(C11:N11),0)),"-") -> - | EA11: =IFERROR(IF(COUNTIF(O11:Z11,"-"),"A",ROUND(AVERAGE(O11:Z11),0)),"-") -> - | EB11: =IFERROR(IF(COUNTIF(AA11:AL11,"-"),"A",ROUND(AVERAGE(AA11:AL11),0)),"-") -> - | EC11: =IFERROR(IF(COUNTIF(AM11:AX11,"-"),"A",ROUND(AVERAGE(AM11:AX11),0)),"-") -> - | ED11: =IFERROR(IF(COUNTIF(AY11:BJ11,"-"),"A",ROUND(AVERAGE(AY11:BJ11),0)),"-") -> - | EE11: =IFERROR(IF(COUNTIF(BK11:BV11,"-"),"A",ROUND(AVERAGE(BK11:BV11),0)),"-") -> - | EF11: =IFERROR(IF(COUNTIF(BW11:CH11,"-"),"A",ROUND(AVERAGE(BW11:CH11),0)),"-") -> - | EG11: =IFERROR(IF(COUNTIF(CI11:CT11,"-"),"A",ROUND(AVERAGE(CI11:CT11),0)),"-") -> - | EH11: =IFERROR(IF(COUNTIF(CU11:DF11,"-"),"A",ROUND(AVERAGE(CU11:DF11),0)),"-") -> - | EI11: =IFERROR(ROUND(AVERAGE(DZ11:EH11),0),"") | EN11: {=IFERROR(_xlfn.XLOOKUP($A11&$B11,MARZO!$D$11:$D$40&MARZO!$E$11:$E$40,MARZO!$AK$11:$AK$40,_xlfn.XLOOKUP($A11&$B11,MARZO!$BC$11:$BC$40&MARZO!$BD$11:$BD$40,MARZO!$CJ$11:$CJ$40,"A")),"")} -> 0 | EO11: {=IFERROR(_xlfn.XLOOKUP($A11&$B11,ABRIL!$D$11:$D$40&ABRIL!$E$11:$E$40,ABRIL!$AK$11:$AK$40,_xlfn.XLOOKUP($A11&$B11,ABRIL!$BC$11:$BC$40&ABRIL!$BD$11:$BD$40,ABRIL!$CJ$11:$CJ$40,"A")),"")} -> 0 | EP11: {=IFERROR(_xlfn.XLOOKUP($A11&$B11,'ABRIL 2'!$D$11:$D$40&'ABRIL 2'!$E$11:$E$40,'ABRIL 2'!$AK$11:$AK$40,_xlfn.XLOOKUP($A11&$B11,'ABRIL 2'!$BC$11:$BC$40&'ABRIL 2'!$BD$11:$BD$40,'ABRIL 2'!$CJ$11:$CJ$40,"A")),"")} -> 0 | EQ11: {=IFERROR(_xlfn.XLOOKUP($A11&$B11,MAYO!$D$11:$D$40&MAYO!$E$11:$E$40,MAYO!$AK$11:$AK$40,_xlfn.XLOOKUP($A11&$B11,MAYO!$BC$11:$BC$40&MAYO!$BD$11:$BD$40,MAYO!$CJ$11:$CJ$40,"A")),"")} -> 0 | ER11: {=IFERROR(_xlfn.XLOOKUP($A11&$B11,'MAYO 2'!$D$11:$D$40&'MAYO 2'!$E$11:$E$40,'MAYO 2'!$AK$11:$AK$40,_xlfn.XLOOKUP($A11&$B11,'MAYO 2'!$BC$11:$BC$40&'MAYO 2'!$BD$11:$BD$40,'MAYO 2'!$CJ$11:$CJ$40,"A")),"")} -> 0 | ES11: {=IFERROR(_xlfn.XLOOKUP($A11&$B11,JUNIO!$D$11:$D$40&JUNIO!$E$11:$E$40,JUNIO!$AK$11:$AK$40,_xlfn.XLOOKUP($A11&$B11,JUNIO!$BC$11:$BC$40&JUNIO!$BD$11:$BD$40,JUNIO!$CJ$11:$CJ$40,"A")),"")} -> 0 | ET11: {=IFERROR(_xlfn.XLOOKUP($A11&$B11,'JUNIO 2'!$D$11:$D$40&'JUNIO 2'!$E$11:$E$40,'JUNIO 2'!$AK$11:$AK$40,_xlfn.XLOOKUP($A11&$B11,'JUNIO 2'!$BC$11:$BC$40&'JUNIO 2'!$BD$11:$BD$40,'JUNIO 2'!$CJ$11:$CJ$40,"A")),"")} -> 0 | EU11: {=IFERROR(_xlfn.XLOOKUP($A11&$B11,JULIO!$D$11:$D$40&JULIO!$E$11:$E$40,JULIO!$AK$11:$AK$40,_xlfn.XLOOKUP($A11&$B11,JULIO!$BC$11:$BC$40&JULIO!$BD$11:$BD$40,JULIO!$CJ$11:$CJ$40,"A")),"")} -> 0 | EV11: {=IFERROR(_xlfn.XLOOKUP($A11&$B11,'JULIO 2'!$D$11:$D$40&'JULIO 2'!$E$11:$E$40,'JULIO 2'!$AK$11:$AK$40,_xlfn.XLOOKUP($A11&$B11,'JULIO 2'!$BC$11:$BC$40&'JULIO 2'!$BD$11:$BD$40,'JULIO 2'!$CJ$11:$CJ$40,"A")),"")} -> 0 | EW11: {=IFERROR(_xlfn.XLOOKUP($A11&$B11,AGOSTO!$D$11:$D$40&AGOSTO!$E$11:$E$40,AGOSTO!$AK$11:$AK$40,_xlfn.XLOOKUP($A11&$B11,AGOSTO!$BC$11:$BC$40&AGOSTO!$BD$11:$BD$40,AGOSTO!$CJ$11:$CJ$40,"A")),"")} -> 0 | EX11: {=IFERROR(_xlfn.XLOOKUP($A11&$B11,'AGOSTO 2'!$D$11:$D$40&'AGOSTO 2'!$E$11:$E$40,'AGOSTO 2'!$AK$11:$AK$40,_xlfn.XLOOKUP($A11&$B11,'AGOSTO 2'!$BC$11:$BC$40&'AGOSTO 2'!$BD$11:$BD$40,'AGOSTO 2'!$CJ$11:$CJ$40,"A")),"")} -> 0 | EY11: {=IFERROR(_xlfn.XLOOKUP($A11&$B11,SEPTIEMBRE!$D$11:$D$40&SEPTIEMBRE!$E$11:$E$40,SEPTIEMBRE!$AK$11:$AK$40,_xlfn.XLOOKUP($A11&$B11,SEPTIEMBRE!$BC$11:$BC$40&SEPTIEMBRE!$BD$11:$BD$40,SEPTIEMBRE!$CJ$11:$CJ$40,"A")),"")} -> 0 | EZ11: {=IFERROR(_xlfn.XLOOKUP($A11&$B11,'SEPTIEMBRE 2'!$D$11:$D$40&'SEPTIEMBRE 2'!$E$11:$E$40,'SEPTIEMBRE 2'!$AK$11:$AK$40,_xlfn.XLOOKUP($A11&$B11,'SEPTIEMBRE 2'!$BC$11:$BC$40&'SEPTIEMBRE 2'!$BD$11:$BD$40,'SEPTIEMBRE 2'!$CJ$11:$CJ$40,"A")),"")} -> 0 | FA11: {=IFERROR(_xlfn.XLOOKUP($A11&$B11,'SEPTIEMBRE 3'!$D$11:$D$40&'SEPTIEMBRE 3'!$E$11:$E$40,'SEPTIEMBRE 3'!$AK$11:$AK$40,_xlfn.XLOOKUP($A11&$B11,'SEPTIEMBRE 3'!$BC$11:$BC$40&'SEPTIEMBRE 3'!$BD$11:$BD$40,'SEPTIEMBRE 3'!$CJ$11:$CJ$40,"A")),"")} -> 0 | FB11: {=IFERROR(_xlfn.XLOOKUP($A11&$B11,OCTUBRE!$D$11:$D$40&OCTUBRE!$E$11:$E$40,OCTUBRE!$AK$11:$AK$40,_xlfn.XLOOKUP($A11&$B11,OCTUBRE!$BC$11:$BC$40&OCTUBRE!$BD$11:$BD$40,OCTUBRE!$CJ$11:$CJ$40,"A")),"")} -> 0 | FC11: {=IFERROR(_xlfn.XLOOKUP($A11&$B11,'OCTUBRE 2'!$D$11:$D$40&'OCTUBRE 2'!$E$11:$E$40,'OCTUBRE 2'!$AK$11:$AK$40,_xlfn.XLOOKUP($A11&$B11,'OCTUBRE 2'!$BC$11:$BC$40&'OCTUBRE 2'!$BD$11:$BD$40,'OCTUBRE 2'!$CJ$11:$CJ$40,"A")),"")} -> 0 | FD11: {=IFERROR(_xlfn.XLOOKUP($A11&$B11,NOVIEMBRE!$D$11:$D$40&NOVIEMBRE!$E$11:$E$40,NOVIEMBRE!$AK$11:$AK$40,_xlfn.XLOOKUP($A11&$B11,NOVIEMBRE!$BC$11:$BC$40&NOVIEMBRE!$BD$11:$BD$40,NOVIEMBRE!$CJ$11:$CJ$40,"A")),"")} -> 0 | FE11: {=IFERROR(_xlfn.XLOOKUP($A11&$B11,'NOVIEMBRE 2'!$D$11:$D$40&'NOVIEMBRE 2'!$E$11:$E$40,'NOVIEMBRE 2'!$AK$11:$AK$40,_xlfn.XLOOKUP($A11&$B11,'NOVIEMBRE 2'!$BC$11:$BC$40&'NOVIEMBRE 2'!$BD$11:$BD$40,'NOVIEMBRE 2'!$CJ$11:$CJ$40,"A")),"")} -> 0 | FF11: {=IFERROR(_xlfn.XLOOKUP($A11&$B11,DICIEMBRE!$D$11:$D$40&DICIEMBRE!$E$11:$E$40,DICIEMBRE!$AK$11:$AK$40,_xlfn.XLOOKUP($A11&$B11,DICIEMBRE!$BC$11:$BC$40&DICIEMBRE!$BD$11:$BD$40,DICIEMBRE!$CJ$11:$CJ$40,"A")),"")} -> 0 | FG11: =IF( AND(N11="", Z11="", AL11="", AX11="", BJ11="", BV11="", CH11="", CT11="",DF11=""), "", TEXTJOIN( " ", TRUE, IF(AND(N11<>"", N11>=40, COUNTA(C11:M11)=0), "⚠️Faltan notas del Módulo I", ""), IF(AND(Z11<>"", Z11>=40, COUNTA(O11:Y11)=0), "⚠️Faltan notas del Módulo II", ""), IF(AND(AL11<>"", AL11>=40, COUNTA(AA11:AK11)=0), "⚠️Faltan notas del Módulo III", ""), IF(AND(AX11<>"", AX11>=40, COUNTA(AM11:AW11)=0), "⚠️Faltan notas del Módulo IV", ""), IF(AND(BJ11<>"", BJ11>=40, COUNTA(AY11:BI11)=0), "⚠️Faltan notas del Módulo V", ""), IF(AND(BV11<>"", BV11>=40, COUNTA(BK11:BU11)=0), "⚠️Faltan notas del Módulo VI", ""), IF(AND(CH11<>"", CH11>=40, COUNTA(BW11:CG11)=0), "⚠️Faltan notas del Módulo VII", ""), IF(AND(CT11<>"", CT11>=40, COUNTA(CI11:CS11)=0), "⚠️Faltan notas del Módulo VIII", ""), IF(AND(DF11<>"", DF11>=40, COUNTA(CU11:DE11)=0), "⚠️Faltan notas del Módulo IX", "") ) ) | FH11: {=IF( COUNT(DZ11:EH11)=0, "-", IF( COUNT(DZ11:EH11) < COUNTA(DZ11:EH11), REPT("🟩", ROUND(COUNT(DZ11:EH11)/COUNTA(DZ11:EH11)*5, 0)) & REPT("⬜", 5 - ROUND(COUNT(DZ11:EH11)/COUNTA(DZ11:EH11)*5, 0)), IF( AVERAGE(IF(DZ11:EH11<>"", DZ11:EH11, )) >= 70, "🟩🟩🟩🟩🟩", IF( AVERAGE(IF(DZ11:EH11<>"",DZ11:EH11, )) >= 56, "🟨🟨🟨🟨🟨", "🟥🟥🟥🟥🟥" ) ) ) )} -> -
N12: =IFERROR(SUM(DT12:DU12)/SUM($DT$7:$DU$7)*100,"") | Z12: =IFERROR(SUM(EB12:EC12)/SUM($EB$7:$EC$7)*100,"") | AL12: =IFERROR(SUM(EK12:EL12)/SUM($EK$7:$EL$7)*100,"") | AX12: =IFERROR(SUM(EW12:EY12)/SUM($EW$7:$EY$7)*100,"") | BJ12: =IFERROR(SUM(EZ12)/SUM($EZ$7)*100,"") | BV12: =IFERROR(SUM(FA12:FB12)/SUM($FA$7:$FB$7)*100,"") | CH12: =IFERROR(SUM(FC12:FD12)/SUM($FC$7:$FD$7)*100,"") | CT12: =IFERROR(SUM(FE12:FF12)/SUM($FE$7:$FF$7)*100,"") | DG12: {=IFERROR(_xlfn.XLOOKUP($A12&B12,MARZO!$D$11:$D$40&MARZO!$E$11:$E$40,MARZO!$AM$11:$AM$40,_xlfn.XLOOKUP($A12&$B12,MARZO!$BC$11:$BC$40&MARZO!$BD$11:$BD$40,MARZO!$CL$11:$CL$40,"A"))/1%,"")} | DH12: {=IFERROR(_xlfn.XLOOKUP($A12&$B12,ABRIL!$D$11:$D$40&ABRIL!$E$11:$E$40,ABRIL!$AM$11:$AM$40,_xlfn.XLOOKUP($A12&$B12,ABRIL!$BC$11:$BC$40&ABRIL!$BD$11:$BD$40,ABRIL!$CL$11:$CL$40,"A"))/1%,"")} | DI12: {=IFERROR(_xlfn.XLOOKUP($A12&$B12,'ABRIL 2'!$D$11:$D$40&'ABRIL 2'!$E$11:$E$40,'ABRIL 2'!$AM$11:$AM$40,_xlfn.XLOOKUP($A12&$B12,'ABRIL 2'!$BC$11:$BC$40&'ABRIL 2'!$BD$11:$BD$40,'ABRIL 2'!$CL$11:$CL$40,"A"))/1%,"")} | DJ12: {=IFERROR(_xlfn.XLOOKUP($A12&$B12,MAYO!$D$11:$D$40&MAYO!$E$11:$E$40,MAYO!$AM$11:$AM$40,_xlfn.XLOOKUP($A12&$B12,MAYO!$BC$11:$BC$40&MAYO!$BD$11:$BD$40,MAYO!$CL$11:$CL$40,"A"))/1%,"")} | DK12: {=IFERROR(_xlfn.XLOOKUP($A12&$B12,'MAYO 2'!$D$11:$D$40&'MAYO 2'!$E$11:$E$40,'MAYO 2'!$AM$11:$AM$40,_xlfn.XLOOKUP($A12&$B12,'MAYO 2'!$BC$11:$BC$40&'MAYO 2'!$BD$11:$BD$40,'MAYO 2'!$CL$11:$CL$40,"A"))/1%,"")} | DL12: {=IFERROR(_xlfn.XLOOKUP($A12&$B12,JUNIO!$D$11:$D$40&JUNIO!$E$11:$E$40,JUNIO!$AM$11:$AM$40,_xlfn.XLOOKUP($A12&$B12,JUNIO!$BC$11:$BC$40&JUNIO!$BD$11:$BD$40,JUNIO!$CL$11:$CL$40,"A"))/1%,"")} | DM12: {=IFERROR(_xlfn.XLOOKUP($A12&$B12,'JUNIO 2'!$D$11:$D$40&'JUNIO 2'!$E$11:$E$40,'JUNIO 2'!$AM$11:$AM$40,_xlfn.XLOOKUP($A12&$B12,'JUNIO 2'!$BC$11:$BC$40&'JUNIO 2'!$BD$11:$BD$40,'JUNIO 2'!$CL$11:$CL$40,"A"))/1%,"")} | DN12: {=IFERROR(_xlfn.XLOOKUP($A12&$B12,JULIO!$D$11:$D$40&JULIO!$E$11:$E$40,JULIO!$AM$11:$AM$40,_xlfn.XLOOKUP($A12&$B12,JULIO!$BC$11:$BC$40&JULIO!$BD$11:$BD$40,JULIO!$CL$11:$CL$40,"A"))/1%,"")} | DO12: {=IFERROR(_xlfn.XLOOKUP($A12&$B12,'JULIO 2'!$D$11:$D$40&'JULIO 2'!$E$11:$E$40,'JULIO 2'!$AM$11:$AM$40,_xlfn.XLOOKUP($A12&$B12,'JULIO 2'!$BC$11:$BC$40&'JULIO 2'!$BD$11:$BD$40,'JULIO 2'!$CL$11:$CL$40,"A"))/1%,"")} | DP12: {=IFERROR(_xlfn.XLOOKUP($A12&$B12,AGOSTO!$D$11:$D$40&AGOSTO!$E$11:$E$40,AGOSTO!$AM$11:$AM$40,_xlfn.XLOOKUP($A12&$B12,AGOSTO!$BC$11:$BC$40&AGOSTO!$BD$11:$BD$40,AGOSTO!$CL$11:$CL$40,"A"))/1%,"")} | DQ12: {=IFERROR(_xlfn.XLOOKUP($A12&$B12,'AGOSTO 2'!$D$11:$D$40&'AGOSTO 2'!$E$11:$E$40,'AGOSTO 2'!$AM$11:$AM$40,_xlfn.XLOOKUP($A12&$B12,'AGOSTO 2'!$BC$11:$BC$40&'AGOSTO 2'!$BD$11:$BD$40,'AGOSTO 2'!$CL$11:$CL$40,"A"))/1%,"")} | DR12: {=IFERROR(_xlfn.XLOOKUP($A12&$B12,SEPTIEMBRE!$D$11:$D$40&SEPTIEMBRE!$E$11:$E$40,SEPTIEMBRE!$AM$11:$AM$40,_xlfn.XLOOKUP($A12&$B12,SEPTIEMBRE!$BC$11:$BC$40&SEPTIEMBRE!$BD$11:$BD$40,SEPTIEMBRE!$CL$11:$CL$40,"A"))/1%,"")} | DS12: {=IFERROR(_xlfn.XLOOKUP($A12&$B12,'SEPTIEMBRE 2'!$D$11:$D$40&'SEPTIEMBRE 2'!$E$11:$E$40,'SEPTIEMBRE 2'!$AM$11:$AM$40,_xlfn.XLOOKUP($A12&$B12,'SEPTIEMBRE 2'!$BC$11:$BC$40&'SEPTIEMBRE 2'!$BD$11:$BD$40,'SEPTIEMBRE 2'!$CL$11:$CL$40,"A"))/1%,"")} | DT12: {=IFERROR(_xlfn.XLOOKUP($A12&$B12,'SEPTIEMBRE 3'!$D$11:$D$40&'SEPTIEMBRE 3'!$E$11:$E$40,'SEPTIEMBRE 3'!$AM$11:$AM$40,_xlfn.XLOOKUP($A12&$B12,'SEPTIEMBRE 3'!$BC$11:$BC$40&'SEPTIEMBRE 3'!$BD$11:$BD$40,'SEPTIEMBRE 3'!$CL$11:$CL$40,"A"))/1%,"")} | DU12: {=IFERROR(_xlfn.XLOOKUP($A12&$B12,OCTUBRE!$D$11:$D$40&OCTUBRE!$E$11:$E$40,OCTUBRE!$AM$11:$AM$40,_xlfn.XLOOKUP($A12&$B12,OCTUBRE!$BC$11:$BC$40&OCTUBRE!$BD$11:$BD$40,OCTUBRE!$CL$11:$CL$40,"A"))/1%,"")} | DV12: {=IFERROR(_xlfn.XLOOKUP($A12&$B12,'OCTUBRE 2'!$D$11:$D$40&'OCTUBRE 2'!$E$11:$E$40,'OCTUBRE 2'!$AM$11:$AM$40,_xlfn.XLOOKUP($A12&$B12,'OCTUBRE 2'!$BC$11:$BC$40&'OCTUBRE 2'!$BD$11:$BD$40,'OCTUBRE 2'!$CL$11:$CL$40,"A"))/1%,"")} | DW12: {=IFERROR(_xlfn.XLOOKUP($A12&$B12,NOVIEMBRE!$D$11:$D$40&NOVIEMBRE!$E$11:$E$40,NOVIEMBRE!$AM$11:$AM$40,_xlfn.XLOOKUP($A12&$B12,NOVIEMBRE!$BC$11:$BC$40&NOVIEMBRE!$BD$11:$BD$40,NOVIEMBRE!$CL$11:$CL$40,"A"))/1%,"")} | DX12: {=IFERROR(_xlfn.XLOOKUP($A12&$B12,'NOVIEMBRE 2'!$D$11:$D$40&'NOVIEMBRE 2'!$E$11:$E$40,'NOVIEMBRE 2'!$AM$11:$AM$40,_xlfn.XLOOKUP($A12&$B12,'NOVIEMBRE 2'!$BC$11:$BC$40&'NOVIEMBRE 2'!$BD$11:$BD$40,'NOVIEMBRE 2'!$CL$11:$CL$40,"A"))/1%,"")} | DY12: {=IFERROR(_xlfn.XLOOKUP($A12&$B12,DICIEMBRE!$D$11:$D$40&DICIEMBRE!$E$11:$E$40,DICIEMBRE!$AM$11:$AM$40,_xlfn.XLOOKUP($A12&$B12,DICIEMBRE!$BC$11:$BC$40&DICIEMBRE!$BD$11:$BD$40,DICIEMBRE!$CL$11:$CL$40,"A"))/1%,"")} | DZ12: =IFERROR(IF(COUNTIF(C12:N12,"-"),"A",ROUND(AVERAGE(C12:N12),0)),"-") -> - | EA12: =IFERROR(IF(COUNTIF(O12:Z12,"-"),"A",ROUND(AVERAGE(O12:Z12),0)),"-") -> - | EB12: =IFERROR(IF(COUNTIF(AA12:AL12,"-"),"A",ROUND(AVERAGE(AA12:AL12),0)),"-") -> - | EC12: =IFERROR(IF(COUNTIF(AM12:AX12,"-"),"A",ROUND(AVERAGE(AM12:AX12),0)),"-") -> - | ED12: =IFERROR(IF(COUNTIF(AY12:BJ12,"-"),"A",ROUND(AVERAGE(AY12:BJ12),0)),"-") -> - | EE12: =IFERROR(IF(COUNTIF(BK12:BV12,"-"),"A",ROUND(AVERAGE(BK12:BV12),0)),"-") -> - | EF12: =IFERROR(IF(COUNTIF(BW12:CH12,"-"),"A",ROUND(AVERAGE(BW12:CH12),0)),"-") -> - | EG12: =IFERROR(IF(COUNTIF(CI12:CT12,"-"),"A",ROUND(AVERAGE(CI12:CT12),0)),"-") -> - | EH12: =IFERROR(IF(COUNTIF(CU12:DF12,"-"),"A",ROUND(AVERAGE(CU12:DF12),0)),"-") -> - | EI12: =IFERROR(ROUND(AVERAGE(DZ12:EH12),0),"") | EN12: {=IFERROR(_xlfn.XLOOKUP($A12&$B12,MARZO!$D$11:$D$40&MARZO!$E$11:$E$40,MARZO!$AK$11:$AK$40,_xlfn.XLOOKUP($A12&$B12,MARZO!$BC$11:$BC$40&MARZO!$BD$11:$BD$40,MARZO!$CJ$11:$CJ$40,"A")),"")} -> 0 | EO12: {=IFERROR(_xlfn.XLOOKUP($A12&$B12,ABRIL!$D$11:$D$40&ABRIL!$E$11:$E$40,ABRIL!$AK$11:$AK$40,_xlfn.XLOOKUP($A12&$B12,ABRIL!$BC$11:$BC$40&ABRIL!$BD$11:$BD$40,ABRIL!$CJ$11:$CJ$40,"A")),"")} -> 0 | EP12: {=IFERROR(_xlfn.XLOOKUP($A12&$B12,'ABRIL 2'!$D$11:$D$40&'ABRIL 2'!$E$11:$E$40,'ABRIL 2'!$AK$11:$AK$40,_xlfn.XLOOKUP($A12&$B12,'ABRIL 2'!$BC$11:$BC$40&'ABRIL 2'!$BD$11:$BD$40,'ABRIL 2'!$CJ$11:$CJ$40,"A")),"")} -> 0 | EQ12: {=IFERROR(_xlfn.XLOOKUP($A12&$B12,MAYO!$D$11:$D$40&MAYO!$E$11:$E$40,MAYO!$AK$11:$AK$40,_xlfn.XLOOKUP($A12&$B12,MAYO!$BC$11:$BC$40&MAYO!$BD$11:$BD$40,MAYO!$CJ$11:$CJ$40,"A")),"")} -> 0 | ER12: {=IFERROR(_xlfn.XLOOKUP($A12&$B12,'MAYO 2'!$D$11:$D$40&'MAYO 2'!$E$11:$E$40,'MAYO 2'!$AK$11:$AK$40,_xlfn.XLOOKUP($A12&$B12,'MAYO 2'!$BC$11:$BC$40&'MAYO 2'!$BD$11:$BD$40,'MAYO 2'!$CJ$11:$CJ$40,"A")),"")} -> 0 | ES12: {=IFERROR(_xlfn.XLOOKUP($A12&$B12,JUNIO!$D$11:$D$40&JUNIO!$E$11:$E$40,JUNIO!$AK$11:$AK$40,_xlfn.XLOOKUP($A12&$B12,JUNIO!$BC$11:$BC$40&JUNIO!$BD$11:$BD$40,JUNIO!$CJ$11:$CJ$40,"A")),"")} -> 0 | ET12: {=IFERROR(_xlfn.XLOOKUP($A12&$B12,'JUNIO 2'!$D$11:$D$40&'JUNIO 2'!$E$11:$E$40,'JUNIO 2'!$AK$11:$AK$40,_xlfn.XLOOKUP($A12&$B12,'JUNIO 2'!$BC$11:$BC$40&'JUNIO 2'!$BD$11:$BD$40,'JUNIO 2'!$CJ$11:$CJ$40,"A")),"")} -> 0 | EU12: {=IFERROR(_xlfn.XLOOKUP($A12&$B12,JULIO!$D$11:$D$40&JULIO!$E$11:$E$40,JULIO!$AK$11:$AK$40,_xlfn.XLOOKUP($A12&$B12,JULIO!$BC$11:$BC$40&JULIO!$BD$11:$BD$40,JULIO!$CJ$11:$CJ$40,"A")),"")} -> 0 | EV12: {=IFERROR(_xlfn.XLOOKUP($A12&$B12,'JULIO 2'!$D$11:$D$40&'JULIO 2'!$E$11:$E$40,'JULIO 2'!$AK$11:$AK$40,_xlfn.XLOOKUP($A12&$B12,'JULIO 2'!$BC$11:$BC$40&'JULIO 2'!$BD$11:$BD$40,'JULIO 2'!$CJ$11:$CJ$40,"A")),"")} -> 0 | EW12: {=IFERROR(_xlfn.XLOOKUP($A12&$B12,AGOSTO!$D$11:$D$40&AGOSTO!$E$11:$E$40,AGOSTO!$AK$11:$AK$40,_xlfn.XLOOKUP($A12&$B12,AGOSTO!$BC$11:$BC$40&AGOSTO!$BD$11:$BD$40,AGOSTO!$CJ$11:$CJ$40,"A")),"")} -> 0 | EX12: {=IFERROR(_xlfn.XLOOKUP($A12&$B12,'AGOSTO 2'!$D$11:$D$40&'AGOSTO 2'!$E$11:$E$40,'AGOSTO 2'!$AK$11:$AK$40,_xlfn.XLOOKUP($A12&$B12,'AGOSTO 2'!$BC$11:$BC$40&'AGOSTO 2'!$BD$11:$BD$40,'AGOSTO 2'!$CJ$11:$CJ$40,"A")),"")} -> 0 | EY12: {=IFERROR(_xlfn.XLOOKUP($A12&$B12,SEPTIEMBRE!$D$11:$D$40&SEPTIEMBRE!$E$11:$E$40,SEPTIEMBRE!$AK$11:$AK$40,_xlfn.XLOOKUP($A12&$B12,SEPTIEMBRE!$BC$11:$BC$40&SEPTIEMBRE!$BD$11:$BD$40,SEPTIEMBRE!$CJ$11:$CJ$40,"A")),"")} -> 0 | EZ12: {=IFERROR(_xlfn.XLOOKUP($A12&$B12,'SEPTIEMBRE 2'!$D$11:$D$40&'SEPTIEMBRE 2'!$E$11:$E$40,'SEPTIEMBRE 2'!$AK$11:$AK$40,_xlfn.XLOOKUP($A12&$B12,'SEPTIEMBRE 2'!$BC$11:$BC$40&'SEPTIEMBRE 2'!$BD$11:$BD$40,'SEPTIEMBRE 2'!$CJ$11:$CJ$40,"A")),"")} -> 0 | FA12: {=IFERROR(_xlfn.XLOOKUP($A12&$B12,'SEPTIEMBRE 3'!$D$11:$D$40&'SEPTIEMBRE 3'!$E$11:$E$40,'SEPTIEMBRE 3'!$AK$11:$AK$40,_xlfn.XLOOKUP($A12&$B12,'SEPTIEMBRE 3'!$BC$11:$BC$40&'SEPTIEMBRE 3'!$BD$11:$BD$40,'SEPTIEMBRE 3'!$CJ$11:$CJ$40,"A")),"")} -> 0 | FB12: {=IFERROR(_xlfn.XLOOKUP($A12&$B12,OCTUBRE!$D$11:$D$40&OCTUBRE!$E$11:$E$40,OCTUBRE!$AK$11:$AK$40,_xlfn.XLOOKUP($A12&$B12,OCTUBRE!$BC$11:$BC$40&OCTUBRE!$BD$11:$BD$40,OCTUBRE!$CJ$11:$CJ$40,"A")),"")} -> 0 | FC12: {=IFERROR(_xlfn.XLOOKUP($A12&$B12,'OCTUBRE 2'!$D$11:$D$40&'OCTUBRE 2'!$E$11:$E$40,'OCTUBRE 2'!$AK$11:$AK$40,_xlfn.XLOOKUP($A12&$B12,'OCTUBRE 2'!$BC$11:$BC$40&'OCTUBRE 2'!$BD$11:$BD$40,'OCTUBRE 2'!$CJ$11:$CJ$40,"A")),"")} -> 0 | FD12: {=IFERROR(_xlfn.XLOOKUP($A12&$B12,NOVIEMBRE!$D$11:$D$40&NOVIEMBRE!$E$11:$E$40,NOVIEMBRE!$AK$11:$AK$40,_xlfn.XLOOKUP($A12&$B12,NOVIEMBRE!$BC$11:$BC$40&NOVIEMBRE!$BD$11:$BD$40,NOVIEMBRE!$CJ$11:$CJ$40,"A")),"")} -> 0 | FE12: {=IFERROR(_xlfn.XLOOKUP($A12&$B12,'NOVIEMBRE 2'!$D$11:$D$40&'NOVIEMBRE 2'!$E$11:$E$40,'NOVIEMBRE 2'!$AK$11:$AK$40,_xlfn.XLOOKUP($A12&$B12,'NOVIEMBRE 2'!$BC$11:$BC$40&'NOVIEMBRE 2'!$BD$11:$BD$40,'NOVIEMBRE 2'!$CJ$11:$CJ$40,"A")),"")} -> 0 | FF12: {=IFERROR(_xlfn.XLOOKUP($A12&$B12,DICIEMBRE!$D$11:$D$40&DICIEMBRE!$E$11:$E$40,DICIEMBRE!$AK$11:$AK$40,_xlfn.XLOOKUP($A12&$B12,DICIEMBRE!$BC$11:$BC$40&DICIEMBRE!$BD$11:$BD$40,DICIEMBRE!$CJ$11:$CJ$40,"A")),"")} -> 0 | FG12: =IF( AND(N12="", Z12="", AL12="", AX12="", BJ12="", BV12="", CH12="", CT12="",DF12=""), "", TEXTJOIN( " ", TRUE, IF(AND(N12<>"", N12>=40, COUNTA(C12:M12)=0), "⚠️Faltan notas del Módulo I", ""), IF(AND(Z12<>"", Z12>=40, COUNTA(O12:Y12)=0), "⚠️Faltan notas del Módulo II", ""), IF(AND(AL12<>"", AL12>=40, COUNTA(AA12:AK12)=0), "⚠️Faltan notas del Módulo III", ""), IF(AND(AX12<>"", AX12>=40, COUNTA(AM12:AW12)=0), "⚠️Faltan notas del Módulo IV", ""), IF(AND(BJ12<>"", BJ12>=40, COUNTA(AY12:BI12)=0), "⚠️Faltan notas del Módulo V", ""), IF(AND(BV12<>"", BV12>=40, COUNTA(BK12:BU12)=0), "⚠️Faltan notas del Módulo VI", ""), IF(AND(CH12<>"", CH12>=40, COUNTA(BW12:CG12)=0), "⚠️Faltan notas del Módulo VII", ""), IF(AND(CT12<>"", CT12>=40, COUNTA(CI12:CS12)=0), "⚠️Faltan notas del Módulo VIII", ""), IF(AND(DF12<>"", DF12>=40, COUNTA(CU12:DE12)=0), "⚠️Faltan notas del Módulo IX", "") ) ) | FH12: {=IF( COUNT(DZ12:EH12)=0, "-", IF( COUNT(DZ12:EH12) < COUNTA(DZ12:EH12), REPT("🟩", ROUND(COUNT(DZ12:EH12)/COUNTA(DZ12:EH12)*5, 0)) & REPT("⬜", 5 - ROUND(COUNT(DZ12:EH12)/COUNTA(DZ12:EH12)*5, 0)), IF( AVERAGE(IF(DZ12:EH12<>"", DZ12:EH12, )) >= 70, "🟩🟩🟩🟩🟩", IF( AVERAGE(IF(DZ12:EH12<>"",DZ12:EH12, )) >= 56, "🟨🟨🟨🟨🟨", "🟥🟥🟥🟥🟥" ) ) ) )} -> -
